Workbook
Name Lastraw: IF('[1]Vehicle Amortization'!Values_Entered,'[1]Vehicle Amortization'!Header_Row+'[1]Vehicle Amortization'!Number_of_Payments,'[1]Vehicle Amortization'!Header_Row)
Name rtr: [2]CapEx_Amortization!$G$18:$G$497

Sheet Sheet1
A1: RPP Scenario | B1: Parking Provider | C1: Parking Meter Type | D1: Enforcement Cost | E1: Parking Management Cost | F1: Cap Ex Amoritized, 10% over 5 yrs | G1: Cap Ex Amoritized, 10% over 3 yrs | H1: YOY Increase
A2: Existing | B2: ACE | C2: Multi-Space | D2: 401723 | E2: =400319+36600+173765 -> 610684 | F2: 193205.27 | G2: 294508.88 | H2: 0.04
A3: Existing | B3: ACE | C3: Single-Space | D3: 415076 | E3: =685168+36600+276025 -> 997793 | F3: 279428.01 | G3: 425940.91 | H3: 0.04
A4: Existing | B4: ACE | C4: Dual-Head | D4: 408476 | E4: =533248+36600+210996 -> 780844 | F4: 188681.41 | G4: 287613.02 | H4: 0.04
A5: Existing | B5: LAZ | C5: Multi-Space | D5: 527863.88 | E5: 321062.14 | F5: =-PMT(10%,5,'Existing RPP - KH Inhouse'!$O$53-'Existing RPP - KH Inhouse'!$O$50) -> 164401.32 | G5: =-PMT(10%,3,'Existing RPP - KH Inhouse'!$O$53-'Existing RPP - KH Inhouse'!$O$50) -> 250602.1 | H5: 0.03
A6: Existing | B6: LAZ | C6: Single-Space | D6: 527863.88 | E6: 321062.14 | F6: =-PMT(10%,5,'Existing RPP - KH Inhouse'!$M$53-'Existing RPP - KH Inhouse'!$M$50) -> 289163.1 | G6: =-PMT(10%,3,'Existing RPP - KH Inhouse'!$M$53-'Existing RPP - KH Inhouse'!$M$50) -> 440780.41 | H6: 0.03
A7: Existing | B7: LAZ | C7: Dual-Head | D7: 527863.88 | E7: 321062.14 | F7: =-PMT(10%,5,'Existing RPP - KH Inhouse'!$N$53-'Existing RPP - KH Inhouse'!$N$50) -> 177692.28 | G7: =-PMT(10%,3,'Existing RPP - KH Inhouse'!$N$53-'Existing RPP - KH Inhouse'!$N$50) -> 270861.94 | H7: 0.03
A8: Expanded | B8: ACE | C8: Multi-Space | D8: 481578 | E8: =400319+36600+173765 -> 610684 | F8: 193205.27 | G8: 294508.88 | H8: 0.04
A9: Expanded | B9: ACE | C9: Single-Space | D9: 493218 | E9: =685168+36600+276025 -> 997793 | F9: 279428.01 | G9: 425940.91 | H9: 0.04
A10: Expanded | B10: ACE | C10: Dual-Head | D10: 487994 | E10: =400319+36600+173765 -> 610684 | F10: 188681.41 | G10: 287613.02 | H10: 0.04
A11: Expanded | B11: LAZ | C11: Multi-Space | D11: 611122.4 | E11: 322043.58 | F11: =-PMT(10%,5,'Expanded RPP - KH Inhouse'!$O$53-'Expanded RPP - KH Inhouse'!$O$50) -> 164401.32 | G11: =-PMT(10%,3,'Expanded RPP - KH Inhouse'!$O$53-'Expanded RPP - KH Inhouse'!$O$50) -> 250602.1 | H11: 0.03
A12: Expanded | B12: LAZ | C12: Single-Space | D12: 611122.4 | E12: 322043.58 | F12: =-PMT(10%,5,'Expanded RPP - KH Inhouse'!$M$53-'Expanded RPP - KH Inhouse'!$M$50) -> 289163.1 | G12: =-PMT(10%,3,'Expanded RPP - KH Inhouse'!$M$53-'Expanded RPP - KH Inhouse'!$M$50) -> 440780.41 | H12: 0.03
A13: Expanded | B13: LAZ | C13: Dual-Head | D13: 611122.4 | E13: 322043.58 | F13: =-PMT(10%,5,'Expanded RPP - KH Inhouse'!$N$53-'Expanded RPP - KH Inhouse'!$N$50) -> 177692.28 | G13: =-PMT(10%,3,'Expanded RPP - KH Inhouse'!$N$53-'Expanded RPP - KH Inhouse'!$N$50) -> 270861.94 | H13: 0.03
A14: Existing | B14: In House | C14: Multi-Space | D14: =SUMIF('Existing RPP - KH Inhouse'!$K$18:$K$37,"Enforcement",'Existing RPP - KH Inhouse'!$L$18:$L$37)+SUMIF('Existing RPP - KH Inhouse'!$K$18:$K$37,"Enforcement",'Existing RPP - KH Inhouse'!$O$18:$O$37)+'Existing RPP - KH Inhouse'!$O$56*(360591.12/558732.7) -> 1089207.8 | E14: =SUMIF('Existing RPP - KH Inhouse'!$K$18:$K$37,"Parking Management",'Existing RPP - KH Inhouse'!$L$18:$L$37)+SUMIF('Existing RPP - KH Inhouse'!$K$18:$K$37,"Parking Management",'Existing RPP - KH Inhouse'!$O$18:$O$37)+'Existing RPP - KH Inhouse'!$O$56*(198141.58/558732.7) -> 682369.75 | F14: =-PMT(10%,5,'Existing RPP - KH Inhouse'!$O$53) -> 187206.87 | G14: =-PMT(10%,3,'Existing RPP - KH Inhouse'!$O$53) -> 285365.33 | H14: =3% -> 0.03
A15: Existing | B15: In House | C15: Single-Space | D15: =SUMIF('Existing RPP - KH Inhouse'!$K$18:$K$37,"Enforcement",'Existing RPP - KH Inhouse'!$L$18:$L$37)+SUMIF('Existing RPP - KH Inhouse'!$K$18:$K$37,"Enforcement",'Existing RPP - KH Inhouse'!$M$18:$M$37)+'Existing RPP - KH Inhouse'!$M$56*(360591.12/558732.7) -> 1347420.7 | E15: =SUMIF('Existing RPP - KH Inhouse'!$K$18:$K$37,"Parking Management",'Existing RPP - KH Inhouse'!$L$18:$L$37)+SUMIF('Existing RPP - KH Inhouse'!$K$18:$K$37,"Parking Management",'Existing RPP - KH Inhouse'!$M$18:$M$37)+'Existing RPP - KH Inhouse'!$M$56*(198141.58/558732.7) -> 872366.67 | F15: =-PMT(10%,5,'Existing RPP - KH Inhouse'!$M$53) -> 327281.83 | G15: =-PMT(10%,3,'Existing RPP - KH Inhouse'!$M$53) -> 498886 | H15: =3% -> 0.03
A16: Existing | B16: In House | C16: Dual-Head | D16: =SUMIF('Existing RPP - KH Inhouse'!$K$18:$K$37,"Enforcement",'Existing RPP - KH Inhouse'!$L$18:$L$37)+SUMIF('Existing RPP - KH Inhouse'!$K$18:$K$37,"Enforcement",'Existing RPP - KH Inhouse'!$N$18:$N$37)+'Existing RPP - KH Inhouse'!$N$56*(360591.12/558732.7) -> 1258550 | E16: =SUMIF('Existing RPP - KH Inhouse'!$K$18:$K$37,"Parking Management",'Existing RPP - KH Inhouse'!$L$18:$L$37)+SUMIF('Existing RPP - KH Inhouse'!$K$18:$K$37,"Parking Management",'Existing RPP - KH Inhouse'!$N$18:$N$37)+'Existing RPP - KH Inhouse'!$N$56*(198141.58/558732.7) -> 787021.03 | F16: =-PMT(10%,5,'Existing RPP - KH Inhouse'!$N$53) -> 208187.27 | G16: =-PMT(10%,3,'Existing RPP - KH Inhouse'!$N$53) -> 317346.41 | H16: =3% -> 0.03
A17: Expanded | B17: In House | C17: Multi-Space | D17: =SUMIF('Expanded RPP - KH Inhouse'!$K$18:$K$37,"Enforcement",'Expanded RPP - KH Inhouse'!$L$18:$L$37)+SUMIF('Expanded RPP - KH Inhouse'!$K$18:$K$37,"Enforcement",'Expanded RPP - KH Inhouse'!$O$18:$O$37)+'Expanded RPP - KH Inhouse'!$O$57*(360591.12/558732.7) -> 1168469.3 | E17: =SUMIF('Expanded RPP - KH Inhouse'!$K$18:$K$37,"Parking Management",'Expanded RPP - KH Inhouse'!$L$18:$L$37)+SUMIF('Expanded RPP - KH Inhouse'!$K$18:$K$37,"Parking Management",'Expanded RPP - KH Inhouse'!$O$18:$O$37)+'Expanded RPP - KH Inhouse'!$O$57*(198141.58/558732.7) -> 725923.23 | F17: =-PMT(10%,5,'Expanded RPP - KH Inhouse'!$O$53) -> 187206.87 | G17: =-PMT(10%,3,'Expanded RPP - KH Inhouse'!$O$53) -> 285365.33 | H17: =3% -> 0.03
A18: Expanded | B18: In House | C18: Single-Space | D18: =SUMIF('Expanded RPP - KH Inhouse'!$K$18:$K$37,"Enforcement",'Expanded RPP - KH Inhouse'!$L$18:$L$37)+SUMIF('Expanded RPP - KH Inhouse'!$K$18:$K$37,"Enforcement",'Expanded RPP - KH Inhouse'!$M$18:$M$37)+'Expanded RPP - KH Inhouse'!$M$57*(360591.12/558732.7) -> 1476674.3 | E18: =SUMIF('Expanded RPP - KH Inhouse'!$K$18:$K$37,"Parking Management",'Expanded RPP - KH Inhouse'!$L$18:$L$37)+SUMIF('Expanded RPP - KH Inhouse'!$K$18:$K$37,"Parking Management",'Expanded RPP - KH Inhouse'!$M$18:$M$37)+'Expanded RPP - KH Inhouse'!$M$57*(198141.58/558732.7) -> 932584.19 | F18: =-PMT(10%,5,'Expanded RPP - KH Inhouse'!$M$53) -> 327281.83 | G18: =-PMT(10%,3,'Expanded RPP - KH Inhouse'!$M$53) -> 498886 | H18: =3% -> 0.03
A19: Expanded | B19: In House | C19: Dual-Head | D19: =SUMIF('Expanded RPP - KH Inhouse'!$K$18:$K$37,"Enforcement",'Expanded RPP - KH Inhouse'!$L$18:$L$37)+SUMIF('Expanded RPP - KH Inhouse'!$K$18:$K$37,"Enforcement",'Expanded RPP - KH Inhouse'!$N$18:$N$37)+'Expanded RPP - KH Inhouse'!$N$57*(360591.12/558732.7) -> 1387803.6 | E19: =SUMIF('Expanded RPP - KH Inhouse'!$K$18:$K$37,"Parking Management",'Expanded RPP - KH Inhouse'!$L$18:$L$37)+SUMIF('Expanded RPP - KH Inhouse'!$K$18:$K$37,"Parking Management",'Expanded RPP - KH Inhouse'!$N$18:$N$37)+'Expanded RPP - KH Inhouse'!$N$57*(198141.58/558732.7) -> 847238.55 | F19: =-PMT(10%,5,'Expanded RPP - KH Inhouse'!$N$53) -> 208187.27 | G19: =-PMT(10%,3,'Expanded RPP - KH Inhouse'!$N$53) -> 317346.41 | H19: =3% -> 0.03

Sheet Inhouse Costs Summary Sheet
A1: City In-House RPP Cost Summary
A2: Consolidated cost assumptions first, followed by the City scenario comparisons — live-linked to both RPP models
A4: 1 | Consolidated Cost Inputs and Calculation Notes
A5: Category | B5: Cost Item | C5: Allocation / Treatment | D5: RPP Applicability | E5: All Scenario Cost | F5: Single-Space | G5: Dual-Head | H5: Multi-Space | I5: Source Row | J5: Calculation Note
A6: Operating | B6: ='Existing RPP - KH Inhouse'!B24 -> LPR On-going Fees | C6: ='Existing RPP - KH Inhouse'!K24 -> Enforcement | D6: Both | E6: ='Existing RPP - KH Inhouse'!L24 -> 12951 | F6: ='Existing RPP - KH Inhouse'!M24 -> 0 | G6: ='Existing RPP - KH Inhouse'!N24 -> 0 | H6: ='Existing RPP - KH Inhouse'!O24 -> 0 | I6: 24 | J6: ='Existing RPP - KH Inhouse'!P24 -> Shared Route1/Genetec annual support and licenses for two ALPR-equipped vehicles, included once across all scenarios; direct annual vendor amount of $12,951. The total fleet may range from 3 to 5 vehicles, but only two are assumed to carry ALPR equipment unless operations determine additional units are needed.
A7: Operating | B7: ='Existing RPP - KH Inhouse'!B27 -> Parking Sensor Software/Support | C7: ='Existing RPP - KH Inhouse'!K27 -> Enforcement | D7: Both | E7: ='Existing RPP - KH Inhouse'!L27 -> 6984 | F7: ='Existing RPP - KH Inhouse'!M27 -> 0 | G7: ='Existing RPP - KH Inhouse'!N27 -> 0 | H7: ='Existing RPP - KH Inhouse'!O27 -> 0 | I7: 27 | J7: ='Existing RPP - KH Inhouse'!P27 -> Shared eleven-x managed network and dashboard subscriptions included once across all selected packages: $4,200 + $2,784 = $6,984 annually.
A8: Operating | B8: ='Existing RPP - KH Inhouse'!B28 -> Turbo Data Handheld Rental | C8: ='Existing RPP - KH Inhouse'!K28 -> Enforcement | D8: Both | E8: ='Existing RPP - KH Inhouse'!L28 -> 7200 | F8: ='Existing RPP - KH Inhouse'!M28 -> 0 | G8: ='Existing RPP - KH Inhouse'!N28 -> 0 | H8: ='Existing RPP - KH Inhouse'!O28 -> 0 | I8: 28 | J8: ='Existing RPP - KH Inhouse'!P28 -> Uses LAZ's flat $7,200 annual Turbodata software-fee allowance for every scenario. No per-device rate is documented, so the cost is not scaled with handheld or officer count.
A9: Operating | B9: ='Existing RPP - KH Inhouse'!B31 -> Signs | C9: ='Existing RPP - KH Inhouse'!K31 -> Enforcement | D9: Both | E9: ='Existing RPP - KH Inhouse'!L31 -> 1800 | F9: ='Existing RPP - KH Inhouse'!M31 -> 0 | G9: ='Existing RPP - KH Inhouse'!N31 -> 0 | H9: ='Existing RPP - KH Inhouse'!O31 -> 0 | I9: 31 | J9: ='Existing RPP - KH Inhouse'!P31 -> ACE annual sign-replacement allowance; common to all scenarios.
A10: Operating | B10: ='Existing RPP - KH Inhouse'!B35 -> Vehicle Fuel | C10: ='Existing RPP - KH Inhouse'!K35 -> Enforcement | D10: Both | E10: ='Existing RPP - KH Inhouse'!L35 -> 0 | F10: ='Existing RPP - KH Inhouse'!M35 -> 14400 | G10: ='Existing RPP - KH Inhouse'!N35 -> 11520 | H10: ='Existing RPP - KH Inhouse'!O35 -> 8640 | I10: 35 | J10: ='Existing RPP - KH Inhouse'!P35 -> LAZ fuel benchmark for the 5-vehicle single-space fleet; scaled to 4 vehicles for dual-space and 3 for multi-space.
A11: Operating | B11: ='Existing RPP - KH Inhouse'!B36 -> Insurance - Vehicle | C11: ='Existing RPP - KH Inhouse'!K36 -> Enforcement | D11: Both | E11: ='Existing RPP - KH Inhouse'!L36 -> 0 | F11: ='Existing RPP - KH Inhouse'!M36 -> 15224 | G11: ='Existing RPP - KH Inhouse'!N36 -> 12179.2 | H11: ='Existing RPP - KH Inhouse'!O36 -> 9134.4 | I11: 36 | J11: ='Existing RPP - KH Inhouse'!P36 -> LAZ vehicle-insurance benchmark for the 5-vehicle single-space fleet; scaled to 4 vehicles for dual-space and 3 for multi-space.
A12: Operating | B12: ='Existing RPP - KH Inhouse'!B18 -> Recruiting/Testing/Training | C12: ='Existing RPP - KH Inhouse'!K18 -> Parking Management | D12: Both | E12: ='Existing RPP - KH Inhouse'!L18 -> 0 | F12: ='Existing RPP - KH Inhouse'!M18 -> 6000 | G12: ='Existing RPP - KH Inhouse'!N18 -> 5500 | H12: ='Existing RPP - KH Inhouse'!O18 -> 4500 | I12: 18 | J12: ='Existing RPP - KH Inhouse'!P18 -> Base Year 1 startup allowance covers 11 hires. Single-space adds 3 hires and dual-space adds 2 hires under the scenario staffing rule; each increment uses $328 per hire plus 20% contingency, rounded to $500.
A13: Operating | B13: ='Existing RPP - KH Inhouse'!B20 -> Uniforms | C13: ='Existing RPP - KH Inhouse'!K20 -> Parking Management | D13: Both | E13: ='Existing RPP - KH Inhouse'!L20 -> 0 | F13: ='Existing RPP - KH Inhouse'!M20 -> 3520 | G13: ='Existing RPP - KH Inhouse'!N20 -> 3200 | H13: ='Existing RPP - KH Inhouse'!O20 -> 2560 | I13: 20 | J13: ='Existing RPP - KH Inhouse'!P20 -> Base allowance covers 8 field staff. Single-space adds uniforms for 3 staff and dual-space for 2 staff at $320 each.
A14: Operating | B14: ='Existing RPP - KH Inhouse'!B21 -> Parking/Meter Supplies | C14: ='Existing RPP - KH Inhouse'!K21 -> Parking Management | D14: Both | E14: ='Existing RPP - KH Inhouse'!L21 -> 0 | F14: ='Existing RPP - KH Inhouse'!M21 -> 24000 | G14: ='Existing RPP - KH Inhouse'!N21 -> 14400 | H14: ='Existing RPP - KH Inhouse'!O21 -> 9000 | I14: 21 | J14: ='Existing RPP - KH Inhouse'!P21 -> Uses ACE's scenario-specific supplies allowances because meter type drives parts and consumables.
A15: Operating | B15: ='Existing RPP - KH Inhouse'!B22 -> Software License Fees | C15: ='Existing RPP - KH Inhouse'!K22 -> Parking Management | D15: Both | E15: ='Existing RPP - KH Inhouse'!L22 -> 15000 | F15: ='Existing RPP - KH Inhouse'!M22 -> 0 | G15: ='Existing RPP - KH Inhouse'!N22 -> 0 | H15: ='Existing RPP - KH Inhouse'!O22 -> 0 | I15: 22 | J15: ='Existing RPP - KH Inhouse'!P22 -> Shared Passport digital-permit license included once across all selected packages; direct annual vendor amount of $15,000.
A16: Operating | B16: ='Existing RPP - KH Inhouse'!B25 -> Meter Software / Data / Support | C16: ='Existing RPP - KH Inhouse'!K25 -> Parking Management | D16: Both | E16: ='Existing RPP - KH Inhouse'!L25 -> 0 | F16: ='Existing RPP - KH Inhouse'!M25 -> 89640 | G16: ='Existing RPP - KH Inhouse'!N25 -> 76296 | H16: ='Existing RPP - KH Inhouse'!O25 -> 72912 | I16: 25 | J16: Vendor-specific recurring component of the selected direct-purchase packages. Current selection is the cheapest option, subject to change based on actual selection: MacKay mkBeacon single-space, MacKay mkBeacon dual-space, and Flowbird CWT S4+ multi-space. Each formula subtracts the shared Passport, eleven-x sensor, and Route1/Genetec costs already included other rows.
A17: Operating | B17: ='Existing RPP - KH Inhouse'!B29 -> Telephone | C17: ='Existing RPP - KH Inhouse'!K29 -> Parking Management | D17: Both | E17: ='Existing RPP - KH Inhouse'!L29 -> 9600 | F17: ='Existing RPP - KH Inhouse'!M29 -> 0 | G17: ='Existing RPP - KH Inhouse'!N29 -> 0 | H17: ='Existing RPP - KH Inhouse'!O29 -> 0 | I17: 29 | J17: ='Existing RPP - KH Inhouse'!P29 -> Uses LAZ's flat $9,600 annual Telephone/Cellular allowance for every scenario. No per-user rate or documented user count is available, so the cost is not scaled with staffing.
A18: Operating | B18: ='Existing RPP - KH Inhouse'!B30 -> Computer Expense | C18: ='Existing RPP - KH Inhouse'!K30 -> Parking Management | D18: Both | E18: ='Existing RPP - KH Inhouse'!L30 -> 3000 | F18: ='Existing RPP - KH Inhouse'!M30 -> 0 | G18: ='Existing RPP - KH Inhouse'!N30 -> 0 | H18: ='Existing RPP - KH Inhouse'!O30 -> 0 | I18: 30 | J18: ='Existing RPP - KH Inhouse'!P30 -> Six computer users × $500 annual device/support allowance: project manager, administrator, IT, enforcement supervisor, operations supervisor, and coordinator.
A19: Operating | B19: ='Existing RPP - KH Inhouse'!B32 -> Repair and Maintenance | C19: ='Existing RPP - KH Inhouse'!K32 -> Parking Management | D19: Both | E19: ='Existing RPP - KH Inhouse'!L32 -> 0 | F19: ='Existing RPP - KH Inhouse'!M32 -> 25200 | G19: ='Existing RPP - KH Inhouse'!N32 -> 8400 | H19: ='Existing RPP - KH Inhouse'!O32 -> 2400 | I19: 32 | J19: ='Existing RPP - KH Inhouse'!P32 -> Uses ACE's scenario-specific repair and maintenance allowances because meter quantity/type drives service effort and parts.
A20: Operating | B20: ='Existing RPP - KH Inhouse'!B33 -> PCI Compliance | C20: ='Existing RPP - KH Inhouse'!K33 -> Parking Management | D20: Both | E20: ='Existing RPP - KH Inhouse'!L33 -> 300 | F20: ='Existing RPP - KH Inhouse'!M33 -> 0 | G20: ='Existing RPP - KH Inhouse'!N33 -> 0 | H20: ='Existing RPP - KH Inhouse'!O33 -> 0 | I20: 33 | J20: ='Existing RPP - KH Inhouse'!P33 -> ACE annual PCI-compliance allowance; common to all scenarios.
A21: Operating | B21: ='Existing RPP - KH Inhouse'!B34 -> Bank Fees | C21: ='Existing RPP - KH Inhouse'!K34 -> Parking Management | D21: Both | E21: ='Existing RPP - KH Inhouse'!L34 -> 264 | F21: ='Existing RPP - KH Inhouse'!M34 -> 0 | G21: ='Existing RPP - KH Inhouse'!N34 -> 0 | H21: ='Existing RPP - KH Inhouse'!O34 -> 0 | I21: 34 | J21: ='Existing RPP - KH Inhouse'!P34 -> ACE annual banking allowance; common to all scenarios. Transaction-based merchant fees remain excluded.
A22: Capital | B22: ='Existing RPP - KH Inhouse'!B49 -> Genetec Mobile LPR Units | C22: ='Existing RPP - KH Inhouse'!K49 -> Enforcement | D22: Both | E22: ='Existing RPP - KH Inhouse'!L49 -> 62474.45 | F22: ='Existing RPP - KH Inhouse'!M49 -> 0 | G22: ='Existing RPP - KH Inhouse'!N49 -> 0 | H22: ='Existing RPP - KH Inhouse'!O49 -> 0 | I22: 49 | J22: ='Existing RPP - KH Inhouse'!P49 -> Shared LAZ/Route1 Genetec mobile LPR capital package for two ALPR-equipped vehicles used in all scenarios: engineering services, hardware/software, user interface and communications, and sales tax. Selected because its lower upfront cost produces the lower five-year total than ACE. The total fleet may range from 3 to 5 vehicles, but Genetec costs are not scaled because only two vehicles are assumed to carry ALPR equipment; obtain an updated Route1 quote if additional ALPR units are required. Annual support/licenses are included separately in L24.
A23: Capital | B23: ='Existing RPP - KH Inhouse'!B50 -> Toyota Corolla | C23: ='Existing RPP - KH Inhouse'!K50 -> Enforcement | D23: Both | E23: ='Existing RPP - KH Inhouse'!L50 -> 0 | F23: ='Existing RPP - KH Inhouse'!M50 -> 144500 | G23: ='Existing RPP - KH Inhouse'!N50 -> 115600 | H23: ='Existing RPP - KH Inhouse'!O50 -> 86451 | I23: 50 | J23: ='Existing RPP - KH Inhouse'!P50 -> Purchase vehicles using ACE's scenario quantities and pricing: 5 vehicles for single-space, 4 for dual-space, and 3 for multi-space.
A24: Capital | B24: ='Existing RPP - KH Inhouse'!B51 -> Parking Sensors | C24: ='Existing RPP - KH Inhouse'!K51 -> Enforcement | D24: Both | E24: ='Existing RPP - KH Inhouse'!L51 -> 40789 | F24: ='Existing RPP - KH Inhouse'!M51 -> 0 | G24: ='Existing RPP - KH Inhouse'!N51 -> 0 | H24: ='Existing RPP - KH Inhouse'!O51 -> 0 | I24: 51 | J24: ='Existing RPP - KH Inhouse'!P51 -> Shared eleven-x installed sensor system used in all scenarios: 48 SPS-X sensors ($9,552), 3 wireless gateways ($3,285), and installation/setup ($27,952), totaling $40,789. Selected over ACE/Fybr because its lower annual cost produces the lower five-year system cost and maintains consistency with the selected LAZ technology packages.
A25: Capital | B25: ='Existing RPP - KH Inhouse'!B48 -> Meters | C25: ='Existing RPP - KH Inhouse'!K48 -> Parking Management | D25: Both | E25: ='Existing RPP - KH Inhouse'!L48 -> 0 | F25: ='Existing RPP - KH Inhouse'!M48 -> 982892.19 | G25: ='Existing RPP - KH Inhouse'!N48 -> 560330.11 | H25: ='Existing RPP - KH Inhouse'!O48 -> 509946.88 | I25: 48 | J25: Selected direct-purchase meter/pay-station capital packages: MacKay mkBeacon single-space (747 meters plus poles, tariffs, tax, shipping, and installation); MacKay mkBeacon dual-space (374 meters plus poles, tariffs, tax, shipping, and installation); and Flowbird CWT S4+ multi-space (62 pay stations plus spare-parts bundle, programming, prevailing-wage installation, freight, and sales tax). Recurring software and support are included separately.
A26: Capital | B26: ='Existing RPP - KH Inhouse'!B52 -> Passport Implementation | C26: ='Existing RPP - KH Inhouse'!K52 -> Parking Management | D26: Both | E26: ='Existing RPP - KH Inhouse'!L52 -> 10000 | F26: ='Existing RPP - KH Inhouse'!M52 -> 0 | G26: ='Existing RPP - KH Inhouse'!N52 -> 0 | H26: ='Existing RPP - KH Inhouse'!O52 -> 0 | I26: 52 | J26: One-time Passport digital-permit implementation charge shared across all scenarios. The annual $15,000 software license is included separately; usage-based permit and payment-processing fees are passed through to users and excluded from City costs.
A27: Labor-driven operating | B27: ='Existing RPP - KH Inhouse'!B37 -> Insurance - Liability | C27: ='Existing RPP - KH Inhouse'!K37 -> Enforcement | D27: Existing | E27: ='Existing RPP - KH Inhouse'!L37 -> 46307.658 | F27: ='Existing RPP - KH Inhouse'!M37 -> 10943.43 | G27: ='Existing RPP - KH Inhouse'!N37 -> 7258.98 | H27: ='Existing RPP - KH Inhouse'!O37 -> 0 | I27: 37 | J27: ='Existing RPP - KH Inhouse'!P37 -> Base planning proxy is 3% of base payroll. Single- and dual-space add 3% of incremental officer and maintenance payroll; replace with the City's actual risk-manager premium when available.
A28: Labor-driven operating | B28: ='Expanded RPP - KH Inhouse'!B37 -> Insurance - Liability | C28: ='Expanded RPP - KH Inhouse'!K37 -> Enforcement | D28: Expanded | E28: ='Expanded RPP - KH Inhouse'!L37 -> 46307.658 | F28: ='Expanded RPP - KH Inhouse'!M37 -> 60935.538 | G28: ='Expanded RPP - KH Inhouse'!N37 -> 57251.088 | H28: ='Expanded RPP - KH Inhouse'!O37 -> 0 | I28: 37 | J28: ='Expanded RPP - KH Inhouse'!P37 -> Base planning proxy is 3% of base payroll. Single- and dual-space add 3% of incremental officer and maintenance payroll; replace with the City's actual risk-manager premium when available.
A29: Labor-driven operating | B29: ='Existing RPP - KH Inhouse'!B19 -> Payroll Processing | C29: ='Existing RPP - KH Inhouse'!K19 -> Parking Management | D29: Existing | E29: ='Existing RPP - KH Inhouse'!L19 -> 0 | F29: ='Existing RPP - KH Inhouse'!M19 -> 19083.696 | G29: ='Existing RPP - KH Inhouse'!N19 -> 17855.546 | H29: ='Existing RPP - KH Inhouse'!O19 -> 15435.886 | I29: 19 | J29: ='Existing RPP - KH Inhouse'!P19 -> Base allowance is 1.0% of base payroll. Single- and dual-space add 1.0% of their incremental officer and maintenance payroll.
A30: Labor-driven operating | B30: ='Expanded RPP - KH Inhouse'!B19 -> Payroll Processing | C30: ='Expanded RPP - KH Inhouse'!K19 -> Parking Management | D30: Expanded | E30: ='Expanded RPP - KH Inhouse'!L19 -> 0 | F30: ='Expanded RPP - KH Inhouse'!M19 -> 35747.732 | G30: ='Expanded RPP - KH Inhouse'!N19 -> 34519.582 | H30: ='Expanded RPP - KH Inhouse'!O19 -> 15435.886 | I30: 19 | J30: ='Expanded RPP - KH Inhouse'!P19 -> Base allowance is 1.0% of base payroll. Single- and dual-space add 1.0% of their incremental officer and maintenance payroll.
A31: Labor | B31: Enforcement Labor | C31: Enforcement | D31: Existing | E31: ='Existing RPP - KH Inhouse'!L58 -> 0 | F31: ='Existing RPP - KH Inhouse'!M58 -> 1231610.6 | G31: ='Existing RPP - KH Inhouse'!N58 -> 1152349.1 | H31: ='Existing RPP - KH Inhouse'!O58 -> 996190.74 | I31: 58 | J31: ="Allocated 65% total labor costs to enforcement per LAZ allocation. " &'Existing RPP - KH Inhouse'!P56 -> Allocated 65% total labor costs to enforcement per LAZ allocation. Total fully burdened labor by equipment plan. Fixed roles are the project manager, administrator, part-time IT specialist, enforcement supervisor, operations supervisor, and operations coordinator. Single-space includes 6 enforcement officers and 2 maintenance workers; dual-space includes 5 officers and 2 maintenance workers; multi-space includes 4 officers and 1 maintenance worker.
A32: Labor | B32: Enforcement Labor | C32: Enforcement | D32: Expanded | E32: ='Expanded RPP - KH Inhouse'!L59 -> 0 | F32: ='Expanded RPP - KH Inhouse'!M59 -> 1310872.1 | G32: ='Expanded RPP - KH Inhouse'!N59 -> 1231610.6 | H32: ='Expanded RPP - KH Inhouse'!O59 -> 1075452.3 | I32: 59 | J32: ="Allocated 65% total labor costs to enforcement per LAZ allocation. " &'Expanded RPP - KH Inhouse'!P57 -> Allocated 65% total labor costs to enforcement per LAZ allocation. Total fully burdened labor for the expanded RPP, including one additional enforcement officer in every equipment scenario compared with the existing RPP. Fixed roles are the project manager, administrator, part-time IT specialist, enforcement supervisor, operations supervisor, and operations coordinator. Single-space includes 7 officers and 2 maintenance workers; dual-space includes 6 officers and 2 maintenance workers; multi-space includes 5 officers and 1 maintenance worker.
A33: Labor | B33: Parking Management Labor | C33: Parking Management | D33: Existing | E33: ='Existing RPP - KH Inhouse'!L57 -> 0 | F33: ='Existing RPP - KH Inhouse'!M57 -> 676758.97 | G33: ='Existing RPP - KH Inhouse'!N57 -> 633205.48 | H33: ='Existing RPP - KH Inhouse'!O57 -> 547397.86 | I33: 57 | J33: ="Allocated 35% total labor costs to enforcement per LAZ allocation." -> Allocated 35% total labor costs to enforcement per LAZ allocation.
A34: Labor | B34: Parking Management Labor | C34: Parking Management | D34: Expanded | E34: ='Expanded RPP - KH Inhouse'!L58 -> 0 | F34: ='Expanded RPP - KH Inhouse'!M58 -> 720312.46 | G34: ='Expanded RPP - KH Inhouse'!N58 -> 676758.97 | H34: ='Expanded RPP - KH Inhouse'!O58 -> 590951.35 | I34: 58 | J34: ="Allocated 35% total labor costs to enforcement per LAZ allocation." -> Allocated 35% total labor costs to enforcement per LAZ allocation.
A36: 2 | Labor Positions and Staffing Costs
A37: Position | B37: Fully Burdened Unit Cost | C37: Existing Single FTE | D37: Existing Dual FTE | E37: Existing Multi FTE | F37: Expanded Single FTE | G37: Expanded Dual FTE | H37: Expanded Multi FTE | I37: Existing Single Cost | J37: Existing Dual Cost | K37: Existing Multi Cost | L37: Expanded Single Cost | M37: Expanded Dual Cost | N37: Expanded Multi Cost
A38: Project Manager | B38: ='Existing RPP - KH Inhouse'!C56 -> 208147 | C38: 1 | D38: 1 | E38: 1 | F38: 1 | G38: 1 | H38: 1 | I38: =B38*C38 -> 208147 | J38: =B38*D38 -> 208147 | K38: =B38*E38 -> 208147 | L38: =B38*F38 -> 208147 | M38: =B38*G38 -> 208147 | N38: =B38*H38 -> 208147
A39: Administrator | B39: ='Existing RPP - KH Inhouse'!C57 -> 164139 | C39: 1 | D39: 1 | E39: 1 | F39: 1 | G39: 1 | H39: 1 | I39: =B39*C39 -> 164139 | J39: =B39*D39 -> 164139 | K39: =B39*E39 -> 164139 | L39: =B39*F39 -> 164139 | M39: =B39*G39 -> 164139 | N39: =B39*H39 -> 164139
A40: IT Specialist II - PT | B40: ='Existing RPP - KH Inhouse'!C58 -> 51313.6 | C40: 1 | D40: 1 | E40: 1 | F40: 1 | G40: 1 | H40: 1 | I40: =B40*C40 -> 51313.6 | J40: =B40*D40 -> 51313.6 | K40: =B40*E40 -> 51313.6 | L40: =B40*F40 -> 51313.6 | M40: =B40*G40 -> 51313.6 | N40: =B40*H40 -> 51313.6
A41: Parking Enforcement Supervisor | B41: ='Existing RPP - KH Inhouse'!C59 -> 186465 | C41: 1 | D41: 1 | E41: 1 | F41: 1 | G41: 1 | H41: 1 | I41: =B41*C41 -> 186465 | J41: =B41*D41 -> 186465 | K41: =B41*E41 -> 186465 | L41: =B41*F41 -> 186465 | M41: =B41*G41 -> 186465 | N41: =B41*H41 -> 186465
A42: Parking Enforcement Officer | B42: ='Existing RPP - KH Inhouse'!C60/4 -> 122815 | C42: 6 | D42: 5 | E42: 4 | F42: 7 | G42: 6 | H42: 5 | I42: =B42*C42 -> 736890 | J42: =B42*D42 -> 614075 | K42: =B42*E42 -> 491260 | L42: =B42*F42 -> 859705 | M42: =B42*G42 -> 736890 | N42: =B42*H42 -> 614075
...

Sheet Expanded RPP - KH Inhouse
B2: Current RPP - Year One Costs
C3: ACE | G3: LAZ | K3: In-House
B4: Operating Expenses | C4: Universal Costs | D4: Single Space | E4: Dual Space | F4: Multi Space | G4: Universal Costs | H4: Single Space | I4: Dual Space | J4: Multi Space | K4: Included in Inhouse Operating Costs? | L4: Universal Costs | M4: Single Space | N4: Dual Space | O4: Multi Space | P4: Calculation Notes
B5: Area Manager Allocation | C5: 18000 | K5: No
B6: Project Manager Wages | C6: 112320 | K6: No
B7: Administrator Wages | C7: 72800 | K7: No
B8: Enforcement Officer Wages | C8: 149760 | K8: No
B9: Meter Support Wages | D9: 187200 | E9: 124800 | F9: 62352 | K9: No
B10: Vacation/Holiday/Sick | D10: 32405 | E10: 27581 | F10: 23822 | G10: ='[3]Budget-Existing_RPP'!P6 -> 23178.96 | K10: No
B11: Payroll Overhead | D11: 147987 | E11: 130610 | F11: 113443 | G11: ='[3]Budget-Existing_RPP'!P8 -> 50572.628 | K11: No
B12: Health and Welfare | D12: 89236 | E12: 76488 | F12: 63740 | G12: ='[3]Budget-Existing_RPP'!P9+'[3]Budget-Existing_RPP'!P11 -> 94801.946 | K12: No
B13: 401k Company Match | G13: ='[3]Budget-Existing_RPP'!P10 -> 3863.16 | K13: No
B14: Safety / Audit Fees | G14: ='[3]Budget-Existing_RPP'!P13 -> 5320 | K14: No
B15: Business License / Parking Bond | G15: ='[3]Budget-Existing_RPP'!P14 -> 2500 | K15: No
B16: IT and Technology / Reporting | G16: ='[3]Budget-Existing_RPP'!P40 -> 9000 | K16: No
B17: Total Labor | D17: 809708 | E17: 712359 | F17: 616036 | G17: ='[3]Budget-Existing_RPP'!P5 -> 386316 | K17: n/a
B18: Recruiting/Testing/Training | D18: 1800 | E18: 900 | F18: 600 | G18: ='[3]Budget-Existing_RPP'!P15 -> 3280 | K18: Parking Management | M18: =CEILING(328*3*1.2,500)+$O$18 -> 6000 | N18: =CEILING(328*2*1.2,500)+O18 -> 5500 | O18: =CEILING(328*11*1.2,500) -> 4500 | P18: Base Year 1 startup allowance covers 11 hires. Single-space adds 3 hires and dual-space adds 2 hires under the scenario staffing rule; each increment uses $328 per hire plus 20% contingency, rounded to $500.
B19: Payroll Processing | D19: 2160 | E19: 1920 | F19: 1680 | G19: ='[3]Budget-Existing_RPP'!P17 -> 3863.16 | K19: Parking Management | M19: =(M57-$L57)*1%+O19 -> 35747.732 | N19: =(N57-$L57)*1%+O19 -> 34519.582 | O19: =SUM($C$57:$C$64)*1% -> 15435.886 | P19: Base allowance is 1.0% of base payroll. Single- and dual-space add 1.0% of their incremental officer and maintenance payroll.
B20: Uniforms | D20: 3240 | E20: 2880 | F20: 2520 | G20: ='[3]Budget-Existing_RPP'!P38 -> 3840 | K20: Parking Management | M20: =320*3+O20 -> 3520 | N20: =320*2+O20 -> 3200 | O20: =320*8 -> 2560 | P20: Base allowance covers 8 field staff. Single-space adds uniforms for 3 staff and dual-space for 2 staff at $320 each.
B21: Parking/Meter Supplies | D21: 24000 | E21: 14400 | F21: 9000 | G21: ='[3]Budget-Existing_RPP'!P34+'[3]Budget-Existing_RPP'!P37+'[3]Budget-Existing_RPP'!P36 -> 8400 | K21: Parking Management | M21: =$D21 -> 24000 | N21: =$E21 -> 14400 | O21: =$F21 -> 9000 | P21: Uses ACE's scenario-specific supplies allowances because meter type drives parts and consumables.
B22: Software License Fees | C22: 780 | G22: ='[3]Budget-Existing_RPP'!P27 -> 15000 | K22: Parking Management | L22: =$G22 -> 15000 | P22: Shared Passport digital-permit license included once across all selected packages; direct annual vendor amount of $15,000.
B23: Vehicles Lease 5 years | G23: ='[3]Budget-Existing_RPP'!P22 -> 30340.78 | K23: No - Purchase as Capital | P23: No recurring lease assumed. The City purchases the vehicles up front; purchase costs are included in capital expenses on row 50.
B24: LPR On-going Fees | G24: ='[3]Budget-Existing_RPP'!P23 -> 12951 | K24: Enforcement | L24: =$G24 -> 12951 | P24: Shared Route1/Genetec annual support and licenses for two ALPR-equipped vehicles, included once across all scenarios; direct annual vendor amount of $12,951. The total fleet may range from 3 to 5 vehicles, but only two are assumed to carry ALPR equipment unless operations determine additional units are needed.
B25: Meter Software / Data / Support | D25: 175172 | E25: 110143 | F25: 72912 | K25: Parking Management | M25: ='[3]Technology Scenarios Total'!G157-$L$22-$L$24-$L$27 -> 89640 | N25: ='[3]Technology Scenarios Total'!G236-$L$22-$L$24-$L$27 -> 76296 | O25: ='[3]Technology Scenarios Total'!G45-$L$22-$L$24-$L$27 -> 72912 | P25: Vendor-specific recurring component of the selected direct-purchase packages: MacKay mkBeacon single-space, MacKay mkBeacon dual-space, and Flowbird CWT S4+ multi-space. Each formula subtracts the shared Passport, eleven-x sensor, and Route1/Genetec costs already included in L22, L27, and L24 from the package annual total.
B26: Genetec Software/Support | C26: 11433 | K26: No - Duplicate | P26: Excluded to avoid double counting. Route1/Genetec annual support and licenses are already included once in L24 as a shared component of every selected technology package.
B27: Parking Sensor Software/Support | C27: 8640 | G27: ='[3]Budget-Existing_RPP'!P30 -> 6984 | K27: Enforcement | L27: =6984 -> 6984 | P27: Shared eleven-x managed network and dashboard subscriptions included once across all selected packages: $4,200 + $2,784 = $6,984 annually.
B28: Turbo Data Handheld Rental | C28: 12600 | G28: ='[3]Budget-Existing_RPP'!P41 -> 7200 | K28: Enforcement | L28: =$G28 -> 7200 | P28: Uses LAZ's flat $7,200 annual Turbodata software-fee allowance for every scenario. No per-device rate is documented, so the cost is not scaled with handheld or officer count.
B29: Telephone | C29: 3000 | G29: ='[3]Budget-Existing_RPP'!P42 -> 9600 | K29: Parking Management | L29: =$G29 -> 9600 | P29: Uses LAZ's flat $9,600 annual Telephone/Cellular allowance for every scenario. No per-user rate or documented user count is available, so the cost is not scaled with staffing.
B30: Computer Expense | C30: 1200 | G30: ='[3]Budget-Existing_RPP'!P43 -> 2500 | K30: Parking Management | L30: =500*6 -> 3000 | P30: Six computer users × $500 annual device/support allowance: project manager, administrator, IT, enforcement supervisor, operations supervisor, and coordinator.
B31: Signs | C31: 1800 | K31: Enforcement | L31: =$C31 -> 1800 | P31: ACE annual sign-replacement allowance; common to all scenarios.
B32: Repair and Maintenance | D32: 25200 | E32: 8400 | F32: 2400 | G32: ='[3]Budget-Existing_RPP'!P32+'[3]Budget-Existing_RPP'!P33 -> 12000 | K32: Parking Management | M32: =$D32 -> 25200 | N32: =$E32 -> 8400 | O32: =$F32 -> 2400 | P32: Uses ACE's scenario-specific repair and maintenance allowances because meter quantity/type drives service effort and parts.
B33: PCI Compliance | C33: 300 | K33: Parking Management | L33: =$C33 -> 300 | P33: ACE annual PCI-compliance allowance; common to all scenarios.
B34: Bank Fees | C34: 264 | K34: Parking Management | L34: =$C34 -> 264 | P34: ACE annual banking allowance; common to all scenarios. Transaction-based merchant fees remain excluded.
B35: Vehicle Fuel | C35: 10200 | G35: ='[3]Budget-Existing_RPP'!P35 -> 14400 | K35: Enforcement | M35: =$G35 -> 14400 | N35: =$G35*4/5 -> 11520 | O35: =$G35*3/5 -> 8640 | P35: LAZ fuel benchmark for the 5-vehicle single-space fleet; scaled to 4 vehicles for dual-space and 3 for multi-space.
B36: Insurance - Vehicle | D36: 79200 | E36: 63360 | F36: 47520 | G36: ='[3]Budget-Existing_RPP'!P20 -> 15224 | K36: Enforcement | M36: =$G36 -> 15224 | N36: =$G36*4/5 -> 12179.2 | O36: =$G36*3/5 -> 9134.4 | P36: LAZ vehicle-insurance benchmark for the 5-vehicle single-space fleet; scaled to 4 vehicles for dual-space and 3 for multi-space.
B37: Insurance - Liability | C37: 9504 | G37: ='[3]Budget-Existing_RPP'!P19 -> 21968.977 | K37: Enforcement | L37: =SUM($C$57:$C$64)*3% -> 46307.658 | M37: =(M57-$L57)*3% -> 60935.538 | N37: =(N57-$L57)*3% -> 57251.088 | P37: Base planning proxy is 3% of base payroll. Single- and dual-space add 3% of incremental officer and maintenance payroll; replace with the City's actual risk-manager premium when available.
B38: Equipment Amortization | D38: 213727 | E38: 150294 | F38: 155855 | G38: ='[3]Budget-Existing_RPP'!P24+'[3]Budget-Existing_RPP'!P29+'[3]Budget-Existing_RPP'!P30+'[3]Budget-Existing_RPP'!P26 -> 40713.41 | K38: No
B39: Storage Space Rental | C39: 6600 | K39: No
B40: Office Space Rental | C40: 30000 | K40: No
B41: Clerical Fee | D41: 11400 | E41: 10200 | F41: 9000 | K41: No
...

Sheet Existing RPP - KH Inhouse
B2: Current RPP - Year One Costs
C3: ACE | G3: LAZ | K3: In-House
B4: Operating Expenses | C4: Universal Costs | D4: Single Space | E4: Dual Space | F4: Multi Space | G4: Universal Costs | H4: Single Space | I4: Dual Space | J4: Multi Space | K4: Included in Inhouse Operating Costs? | L4: Universal Costs | M4: Single Space | N4: Dual Space | O4: Multi Space | P4: Calculation Notes
B5: Area Manager Allocation | C5: 18000 | K5: No
B6: Project Manager Wages | C6: 112320 | K6: No
B7: Administrator Wages | C7: 72800 | K7: No
B8: Enforcement Officer Wages | C8: 149760 | K8: No
B9: Meter Support Wages | D9: 187200 | E9: 124800 | F9: 62352 | K9: No
B10: Vacation/Holiday/Sick | D10: 32405 | E10: 27581 | F10: 23822 | G10: ='[3]Budget-Existing_RPP'!P6 -> 23178.96 | K10: No
B11: Payroll Overhead | D11: 147987 | E11: 130610 | F11: 113443 | G11: ='[3]Budget-Existing_RPP'!P8 -> 50572.628 | K11: No
B12: Health and Welfare | D12: 89236 | E12: 76488 | F12: 63740 | G12: ='[3]Budget-Existing_RPP'!P9+'[3]Budget-Existing_RPP'!P11 -> 94801.946 | K12: No
B13: 401k Company Match | G13: ='[3]Budget-Existing_RPP'!P10 -> 3863.16 | K13: No
B14: Safety / Audit Fees | G14: ='[3]Budget-Existing_RPP'!P13 -> 5320 | K14: No
B15: Business License / Parking Bond | G15: ='[3]Budget-Existing_RPP'!P14 -> 2500 | K15: No
B16: IT and Technology / Reporting | G16: ='[3]Budget-Existing_RPP'!P40 -> 9000 | K16: No
B17: Total Labor | D17: 809708 | E17: 712359 | F17: 616036 | G17: ='[3]Budget-Existing_RPP'!P5 -> 386316 | K17: n/a
B18: Recruiting/Testing/Training | D18: 1800 | E18: 900 | F18: 600 | G18: ='[3]Budget-Existing_RPP'!P15 -> 3280 | K18: Parking Management | M18: =CEILING(328*3*1.2,500)+$O$18 -> 6000 | N18: =CEILING(328*2*1.2,500)+O18 -> 5500 | O18: =CEILING(328*11*1.2,500) -> 4500 | P18: Base Year 1 startup allowance covers 11 hires. Single-space adds 3 hires and dual-space adds 2 hires under the scenario staffing rule; each increment uses $328 per hire plus 20% contingency, rounded to $500.
B19: Payroll Processing | D19: 2160 | E19: 1920 | F19: 1680 | G19: ='[3]Budget-Existing_RPP'!P17 -> 3863.16 | K19: Parking Management | M19: =(M56-$O56)*1%+O19 -> 19083.696 | N19: =(N56-$O56)*1%+O19 -> 17855.546 | O19: =SUM($C$56:$C$63)*1% -> 15435.886 | P19: Base allowance is 1.0% of base payroll. Single- and dual-space add 1.0% of their incremental officer and maintenance payroll.
B20: Uniforms | D20: 3240 | E20: 2880 | F20: 2520 | G20: ='[3]Budget-Existing_RPP'!P38 -> 3840 | K20: Parking Management | M20: =320*3+O20 -> 3520 | N20: =320*2+O20 -> 3200 | O20: =320*8 -> 2560 | P20: Base allowance covers 8 field staff. Single-space adds uniforms for 3 staff and dual-space for 2 staff at $320 each.
B21: Parking/Meter Supplies | D21: 24000 | E21: 14400 | F21: 9000 | G21: ='[3]Budget-Existing_RPP'!P34+'[3]Budget-Existing_RPP'!P37+'[3]Budget-Existing_RPP'!P36 -> 8400 | K21: Parking Management | M21: =$D21 -> 24000 | N21: =$E21 -> 14400 | O21: =$F21 -> 9000 | P21: Uses ACE's scenario-specific supplies allowances because meter type drives parts and consumables.
B22: Software License Fees | C22: 780 | G22: ='[3]Budget-Existing_RPP'!P27 -> 15000 | K22: Parking Management | L22: =$G22 -> 15000 | P22: Shared Passport digital-permit license included once across all selected packages; direct annual vendor amount of $15,000.
B23: Vehicles Lease 5 years | G23: ='[3]Budget-Existing_RPP'!P22 -> 30340.78 | K23: No - Purchase as Capital | P23: No recurring lease assumed. The City purchases the vehicles up front; purchase costs are included in capital expenses on row 50.
B24: LPR On-going Fees | G24: ='[3]Budget-Existing_RPP'!P23 -> 12951 | K24: Enforcement | L24: =$G24 -> 12951 | P24: Shared Route1/Genetec annual support and licenses for two ALPR-equipped vehicles, included once across all scenarios; direct annual vendor amount of $12,951. The total fleet may range from 3 to 5 vehicles, but only two are assumed to carry ALPR equipment unless operations determine additional units are needed.
B25: Meter Software / Data / Support | D25: 175172 | E25: 110143 | F25: 72912 | K25: Parking Management | M25: ='[3]Technology Scenarios Total'!G157-$L$22-$L$24-$L$27 -> 89640 | N25: ='[3]Technology Scenarios Total'!G236-$L$22-$L$24-$L$27 -> 76296 | O25: ='[3]Technology Scenarios Total'!G45-$L$22-$L$24-$L$27 -> 72912 | P25: Vendor-specific recurring component of the selected direct-purchase packages. Current selection is the cheapest option, subject to change based on actual selection: MacKay mkBeacon single-space, MacKay mkBeacon dual-space, and Flowbird CWT S4+ multi-space. Each formula subtracts the shared Passport, eleven-x sensor, and Route1/Genetec costs already included in L22, L27, and L24 from the package annual total.
B26: Genetec Software/Support | C26: 11433 | K26: No - Duplicate | P26: Excluded to avoid double counting. Route1/Genetec annual support and licenses are already included once in L24 as a shared component of every selected technology package.
B27: Parking Sensor Software/Support | C27: 8640 | G27: ='[3]Budget-Existing_RPP'!P30 -> 6984 | K27: Enforcement | L27: =6984 -> 6984 | P27: Shared eleven-x managed network and dashboard subscriptions included once across all selected packages: $4,200 + $2,784 = $6,984 annually.
B28: Turbo Data Handheld Rental | C28: 12600 | G28: ='[3]Budget-Existing_RPP'!P41 -> 7200 | K28: Enforcement | L28: =$G28 -> 7200 | P28: Uses LAZ's flat $7,200 annual Turbodata software-fee allowance for every scenario. No per-device rate is documented, so the cost is not scaled with handheld or officer count.
B29: Telephone | C29: 3000 | G29: ='[3]Budget-Existing_RPP'!P42 -> 9600 | K29: Parking Management | L29: =$G29 -> 9600 | P29: Uses LAZ's flat $9,600 annual Telephone/Cellular allowance for every scenario. No per-user rate or documented user count is available, so the cost is not scaled with staffing.
B30: Computer Expense | C30: 1200 | G30: ='[3]Budget-Existing_RPP'!P43 -> 2500 | K30: Parking Management | L30: =500*6 -> 3000 | P30: Six computer users × $500 annual device/support allowance: project manager, administrator, IT, enforcement supervisor, operations supervisor, and coordinator.
B31: Signs | C31: 1800 | K31: Enforcement | L31: =$C31 -> 1800 | P31: ACE annual sign-replacement allowance; common to all scenarios.
B32: Repair and Maintenance | D32: 25200 | E32: 8400 | F32: 2400 | G32: ='[3]Budget-Existing_RPP'!P32+'[3]Budget-Existing_RPP'!P33 -> 12000 | K32: Parking Management | M32: =$D32 -> 25200 | N32: =$E32 -> 8400 | O32: =$F32 -> 2400 | P32: Uses ACE's scenario-specific repair and maintenance allowances because meter quantity/type drives service effort and parts.
B33: PCI Compliance | C33: 300 | K33: Parking Management | L33: =$C33 -> 300 | P33: ACE annual PCI-compliance allowance; common to all scenarios.
B34: Bank Fees | C34: 264 | K34: Parking Management | L34: =$C34 -> 264 | P34: ACE annual banking allowance; common to all scenarios. Transaction-based merchant fees remain excluded.
B35: Vehicle Fuel | C35: 10200 | G35: ='[3]Budget-Existing_RPP'!P35 -> 14400 | K35: Enforcement | M35: =$G35 -> 14400 | N35: =$G35*4/5 -> 11520 | O35: =$G35*3/5 -> 8640 | P35: LAZ fuel benchmark for the 5-vehicle single-space fleet; scaled to 4 vehicles for dual-space and 3 for multi-space.
B36: Insurance - Vehicle | D36: 79200 | E36: 63360 | F36: 47520 | G36: ='[3]Budget-Existing_RPP'!P20 -> 15224 | K36: Enforcement | M36: =$G36 -> 15224 | N36: =$G36*4/5 -> 12179.2 | O36: =$G36*3/5 -> 9134.4 | P36: LAZ vehicle-insurance benchmark for the 5-vehicle single-space fleet; scaled to 4 vehicles for dual-space and 3 for multi-space.
B37: Insurance - Liability | C37: 9504 | G37: ='[3]Budget-Existing_RPP'!P19 -> 21968.977 | K37: Enforcement | L37: =SUM($C$56:$C$63)*3% -> 46307.658 | M37: =(M56-$O56)*3% -> 10943.43 | N37: =(N56-$O56)*3% -> 7258.98 | P37: Base planning proxy is 3% of base payroll. Single- and dual-space add 3% of incremental officer and maintenance payroll; replace with the City's actual risk-manager premium when available.
B38: Equipment Amortization | D38: 213727 | E38: 150294 | F38: 155855 | G38: ='[3]Budget-Existing_RPP'!P24+'[3]Budget-Existing_RPP'!P29+'[3]Budget-Existing_RPP'!P30+'[3]Budget-Existing_RPP'!P26 -> 40713.41 | K38: No
B39: Storage Space Rental | C39: 6600 | K39: No
B40: Office Space Rental | C40: 30000 | K40: No
B41: Clerical Fee | D41: 11400 | E41: 10200 | F41: 9000 | K41: No
...
