Workbook
Name _Ref155180426: '$1.5 per hr + $0.5 Projection'!#REF!
Name _Ref155180426: '$1.5 per hr + $1 Projection'!#REF!
Name _Ref155180426: '$2 per hr + $0.5 Projection'!#REF!
Name _Ref155180426: '$2 per hr + $1 Projection'!#REF!

Sheet Incl
A1: Phase 1 | B1: Phase 2
A2: 80 | B2: 154 | D2: 80
A3: 81 | B3: 155 | D3: 81
A4: 82 | B4: 156 | D4: 82
A5: 83 | D5: 83
A6: 84 | B6: 158 | D6: 84
A7: 85 | B7: 100 | D7: 85
A8: 194 | B8: 103
A9: 113 | B9: 107
A10: 117 | B10: 109
A11: 196 | B11: 110
A12: 195 | B12: 111
A13: 197 | B13: 80
A14: 120 | B14: 81
A15: 87 | B15: 82
A16: 121 | B16: 83
A17: 86 | B17: 84
A18: 206 | B18: 85
A19: 208 | B19: 194
... A42: 904 | B42: 91
B43: 90
B44: 224
B45: 225
B46: 127
B47: 129
B48: 130
B49: 132
B50: 207
B51: 902
B52: 903
B53: 904
B54: 905

Sheet Raw
A1: OBJECTID_1 * | B1: SymbolID | C1: Shape_Leng | D1: OBJECTID | E1: Join_Count | F1: TARGET_FID | G1: Name | H1: Name_v2 | I1: Field1 | J1: Segment | K1: Street | L1: From | M1: To | N1: Short Term Parking | O1: Medium Term Parking | P1: Unlimited Parking | Q1: Handicapped Parking | R1: Loading Zone | S1: Permitted Parking | T1: Space_Total | U1: Occ_Sat_10AM_CT | V1: Occ_Sat_2PM_CT | W1: Occ_Sat_4PM_CT | X1: Occ_Sat_8PM_CT | Y1: Occ_Sat_10AM_Per | Z1: Occ_Sat_2PM_Per | AA1: Occ_Sat_4PM_Per | AB1: Occ_Sat_8PM_Per | AC1: Occ_Sat_is75 | AD1: Occ_Thu_10AM_CT | AE1: Occ_Thu_2PM_CT | AF1: Occ_Thu_4PM_CT | AG1: Occ_Thu_8PM_CT | AH1: Occ_Thu_10AM_Per | AI1: Occ_Thu_2PM_Per | AJ1: Occ_Thu_4PM_Per | AK1: Occ_Thu_8PM_Per | AL1: Occ_Thu_is75 | AM1: TO_Sat_10AM_CT | AN1: TO_Sat_11AM_CT | AO1: TO_Sat_12PM_CT | AP1: TO_Sat_1PM_CT | AQ1: TO_Sat_2PM_CT | AR1: TO_Sat_3PM_CT | AS1: TO_Sat_4PM_CT | AT1: TO_Sat_5PM_CT | AU1: TO_Sat_6PM_CT | AV1: TO_Sat_7PM_CT | AW1: TO_Sat_0-1 HRS | AX1: TO_Sat_1-2 HRS | AY1: TO_Sat_2-3 HRS | AZ1: TO_Sat_3-4 HRS | BA1: TO_Sat_4-5 HRS | BB1: TO_Sat_5-6 HRS | BC1: TO_Sat_6-7 HRS | BD1: TO_Sat_7-8 HRS | BE1: TO_Sat_8-9 HRS | BF1: TO_Sat_9-10 HRS | BG1: TO_Sat_Total | BH1: TO_Sat_Rate | BI1: TO_Sat_Range | BJ1: TO_Thu_10AM_CT | BK1: TO_Thu_11AM_CT | BL1: TO_Thu_12PM_CT | BM1: TO_Thu_1PM_CT | BN1: TO_Thu_2PM_CT | BO1: TO_Thu_3PM_CT | BP1: TO_Thu_4PM_CT | BQ1: TO_Thu_5PM_CT | BR1: TO_Thu_6PM_CT | BS1: TO_Thu_7PM_CT | BT1: TO_Thu_0-1 HRS | BU1: TO_Thu_1-2 HRS | BV1: TO_Thu_2-3 HRS | BW1: TO_Thu_3-4 HRS | BX1: TO_Thu_4-5 HRS | BY1: TO_Thu_5-6 HRS | BZ1: TO_Thu_6-7 HRS | CA1: TO_Thu_7-8 HRS | CB1: TO_Thu_8-9 HRS | CC1: TO_Thu_9-10 HRS | CD1: TO_Thu_Total | CE1: TO_Thu_Rate | CF1: TO_Thu_Range | CG1: x | CH1: Shape_Length | CI1: Occ_All_is75 | CJ1: PricingBoundary1 | CK1: PricingBoundary2 | CL1: PricingBoundary3 | CM1: Length_ft | CN1: DataAvail | CO1: PricingBoundary4 | CP1: Reduction | CQ1: <Null> | CR1: =IF(COUNTIF(Incl!A:A,Raw!J1),1, "")
AW2: 1 | AX2: 2 | AY2: 3 | AZ2: 4 | BA2: 5 | BB2: 6 | BC2: 7 | BD2: 8 | BE2: 9 | BF2: 10 | BT2: 1 | BU2: 2 | BV2: 3 | BW2: 4 | BX2: 5 | BY2: 6 | BZ2: 7 | CA2: 8 | CB2: 9 | CC2: 10
AW3: 1 | AX3: 2 | AY3: 2 | AZ3: 2 | BA3: 2 | BB3: 2 | BC3: 2 | BD3: 2 | BE3: 2 | BF3: 2 | BT3: 1 | BU3: 2 | BV3: 2 | BW3: 2 | BX3: 2 | BY3: 2 | BZ3: 2 | CA3: 2 | CB3: 2 | CC3: 2
A4: 1 | B4: 1 | C4: 555.51475 | D4: 1 | E4: 1 | F4: 30 | G4: 154 | H4: 154 | I4: 154 | J4: 154 | K4: Park Pl | L4: El Camino Real | M4: Park Blvd | N4: 6 | O4: 10 | P4: NA | Q4: NA | R4: NA | S4: NA | T4: 16 | U4: 11 | V4: 10 | W4: 13 | X4: NA | Y4: 69 | Z4: 63 | AA4: 81 | AB4: 0 | AC4: 1 | AD4: 4 | AE4: 10 | AF4: 15 | AG4: NA | AH4: 25 | AI4: 63 | AJ4: 94 | AK4: 0 | AL4: 1 | AM4: 11 | AN4: 13 | AO4: 13 | AP4: 15 | AQ4: 10 | AR4: 14 | AS4: 16 | AT4: 12 | AU4: 11 | AV4: 12 | AW4: 25 | AX4: 7 | AY4: 4 | AZ4: 4 | BA4: 1 | BB4: 0 | BC4: 1 | BD4: 1 | BE4: 0 | BF4: 4 | BG4: 47 | BH4: 2.9 | BI4: 2.0 - 3.0 | BJ4: 4 | BK4: 11 | BL4: 10 | BM4: 5 | BN4: 10 | BO4: 11 | BP4: 12 | BQ4: 12 | BR4: 15 | BS4: 14 | BT4: 13 | BU4: 7 | BV4: 1 | BW4: 3 | BX4: 1 | BY4: 2 | BZ4: 0 | CA4: 2 | CB4: 1 | CC4: 2 | CD4: 32 | CE4: 2 | CF4: 2.0 - 3.0 | CG4: N | CH4: 0.001581 | CI4: 2 | CJ4: 1 | CK4: 1 | CL4: <Null> | CM4: 555.51482 | CN4: 1 | CO4: 1 | CP4: <Null> | CQ4: <Null> | CR4: =IF(COUNTIF(Incl!A:A,Raw!J4),1, "")
A5: 2 | B5: 1 | C5: 460.32238 | D5: 2 | E5: 1 | F5: 31 | G5: 155 | H5: 155 | I5: 155 | J5: 155 | K5: Park Pl | L5: Park Blvd | M5: El Camino Real | N5: 11 | O5: 7 | P5: NA | Q5: NA | R5: NA | S5: NA | T5: 18 | U5: 10 | V5: 16 | W5: 16 | X5: NA | Y5: 56 | Z5: 89 | AA5: 89 | AB5: 0 | AC5: 2 | AD5: 10 | AE5: 14 | AF5: 17 | AG5: NA | AH5: 56 | AI5: 78 | AJ5: 94 | AK5: 0 | AL5: 2 | AM5: 10 | AN5: 16 | AO5: 18 | AP5: 13 | AQ5: 16 | AR5: 17 | AS5: 17 | AT5: 16 | AU5: 16 | AV5: 16 | AW5: 43 | AX5: 6 | AY5: 8 | AZ5: 3 | BA5: 3 | BB5: 0 | BC5: 0 | BD5: 0 | BE5: 1 | BF5: 4 | BG5: 68 | BH5: 3.8 | BI5: 3.0 - 4.0 | BJ5: 10 | BK5: 12 | BL5: 14 | BM5: 11 | BN5: 14 | BO5: 15 | BP5: 13 | BQ5: 13 | BR5: 17 | BS5: 16 | BT5: 17 | BU5: 7 | BV5: 1 | BW5: 6 | BX5: 3 | BY5: 2 | BZ5: 0 | CA5: 0 | CB5: 0 | CC5: 5 | CD5: 41 | CE5: 2.3 | CF5: 2.0 - 3.0 | CG5: S | CH5: 0.001317 | CI5: 4 | CJ5: 1 | CK5: 1 | CL5: <Null> | CM5: 460.32252 | CN5: 1 | CO5: 1 | CP5: <Null> | CQ5: <Null> | CR5: =IF(COUNTIF(Incl!A:A,Raw!J5),1, "")
A6: 3 | B6: 1 | C6: 472.9842 | D6: 3 | E6: 1 | F6: 32 | G6: 156 | H6: 156 | I6: 156 | J6: 156 | K6: Park Blvd | L6: Park Pl | M6: El Camino Real | N6: 17 | O6: 8 | P6: NA | Q6: NA | R6: NA | S6: NA | T6: 25 | U6: 19 | V6: 17 | W6: 22 | X6: NA | Y6: 76 | Z6: 68 | AA6: 88 | AB6: 0 | AC6: 2 | AD6: 10 | AE6: 11 | AF6: 15 | AG6: NA | AH6: 40 | AI6: 44 | AJ6: 60 | AK6: 0 | AL6: 0 | AM6: 19 | AN6: 23 | AO6: 23 | AP6: 15 | AQ6: 17 | AR6: 10 | AS6: 15 | AT6: 17 | AU6: 22 | AV6: 23 | AW6: 82 | AX6: 15 | AY6: 5 | AZ6: 0 | BA6: 1 | BB6: 3 | BC6: 2 | BD6: 0 | BE6: 0 | BF6: 2 | BG6: 110 | BH6: 4.4 | BI6: 4.0 - 5.0 | BJ6: 10 | BK6: 10 | BL6: 9 | BM6: 13 | BN6: 11 | BO6: 13 | BP6: 14 | BQ6: 16 | BR6: 15 | BS6: 12 | BT6: 19 | BU6: 11 | BV6: 4 | BW6: 1 | BX6: 1 | BY6: 1 | BZ6: 1 | CA6: 0 | CB6: 2 | CC6: 3 | CD6: 43 | CE6: 1.7 | CF6: 1.0 - 2.0 | CG6: N | CH6: 0.001627 | CI6: 2 | CJ6: 1 | CK6: 1 | CL6: <Null> | CM6: 472.98401 | CN6: 1 | CO6: 1 | CP6: <Null> | CQ6: <Null> | CR6: =IF(COUNTIF(Incl!A:A,Raw!J6),1, "")
A7: 4 | B7: 1 | C7: 319.60566 | D7: 4 | E7: 1 | F7: 33 | G7: 157 | H7: 157 | I7: 157 | J7: 157 | K7: Park Blvd | L7: Magnolia Ave | M7: Palmito Dr | N7: NA | O7: 14 | P7: NA | Q7: NA | R7: NA | S7: NA | T7: 14 | U7: 9 | V7: 9 | W7: 9 | X7: 9 | Y7: 64 | Z7: 64 | AA7: 64 | AB7: 64 | AC7: 0 | AD7: 11 | AE7: 13 | AF7: 12 | AG7: 14 | AH7: 79 | AI7: 93 | AJ7: 86 | AK7: 100 | AL7: 4 | AM7: NA | AN7: NA | AO7: NA | AP7: NA | AQ7: NA | AR7: NA | AS7: NA | AT7: NA | AU7: NA | AV7: NA | AW7: NA | AX7: NA | AY7: NA | AZ7: NA | BA7: NA | BB7: NA | BC7: NA | BD7: NA | BE7: NA | BF7: NA | BG7: NA | BH7: NA | BI7: NA | BJ7: NA | BK7: NA | BL7: NA | BM7: NA | BN7: NA | BO7: NA | BP7: NA | BQ7: NA | BR7: NA | BS7: NA | BT7: NA | BU7: NA | BV7: NA | BW7: NA | BX7: NA | BY7: NA | BZ7: NA | CA7: NA | CB7: NA | CC7: NA | CD7: NA | CE7: NA | CF7: NA | CG7: S | CH7: 0.0011 | CI7: 4 | CJ7: 1 | CK7: 1 | CL7: <Null> | CM7: 319.60577 | CN7: 2 | CO7: 0 | CP7: <Null> | CQ7: <Null> | CR7: =IF(COUNTIF(Incl!A:A,Raw!J7),1, "")
A8: 5 | B8: 1 | C8: 175.24878 | D8: 5 | E8: 2 | F8: 34 | G8: 158 | H8: 158 | I8: 158 | J8: 158 | K8: Park Blvd | L8: Palmito Dr | M8: El Camino Real | N8: 11 | O8: NA | P8: NA | Q8: NA | R8: NA | S8: NA | T8: 11 | U8: 5 | V8: 8 | W8: 10 | X8: NA | Y8: 45 | Z8: 73 | AA8: 91 | AB8: 0 | AC8: 1 | AD8: 3 | AE8: 5 | AF8: 3 | AG8: NA | AH8: 27 | AI8: 45 | AJ8: 27 | AK8: 0 | AL8: 0 | AM8: 5 | AN8: 7 | AO8: 7 | AP8: 8 | AQ8: 8 | AR8: 3 | AS8: 4 | AT8: 8 | AU8: 10 | AV8: 11 | AW8: 39 | AX8: 7 | AY8: 2 | AZ8: 1 | BA8: 0 | BB8: 0 | BC8: 0 | BD8: 1 | BE8: 0 | BF8: 0 | BG8: 50 | BH8: 4.5 | BI8: 4.0 - 5.0 | BJ8: 3 | BK8: 5 | BL8: 5 | BM8: 7 | BN8: 5 | BO8: 4 | BP8: 3 | BQ8: 4 | BR8: 3 | BS8: 2 | BT8: 11 | BU8: 1 | BV8: 3 | BW8: 0 | BX8: 1 | BY8: 1 | BZ8: 0 | CA8: 1 | CB8: 0 | CC8: 0 | CD8: 18 | CE8: 1.6 | CF8: 1.0 - 2.0 | CG8: S | CH8: 0.000603 | CI8: 1 | CJ8: 1 | CK8: 1 | CL8: <Null> | CM8: 175.24883 | CN8: 1 | CO8: 1 | CP8: <Null> | CQ8: <Null> | CR8: =IF(COUNTIF(Incl!A:A,Raw!J8),1, "")
A9: 6 | B9: 1 | C9: 461.94848 | D9: 6 | E9: 1 | F9: 35 | G9: 100 | H9: 100 | I9: 100 | J9: 100 | K9: El Camino Real | L9: Park Pl | M9: Park Blvd | N9: 7 | O9: 12 | P9: NA | Q9: NA | R9: NA | S9: NA | T9: 19 | U9: 15 | V9: 11 | W9: 15 | X9: NA | Y9: 81 | Z9: 59 | AA9: 81 | AB9: 0 | AC9: 2 | AD9: 9 | AE9: 17 | AF9: 12 | AG9: NA | AH9: 48 | AI9: 91 | AJ9: 65 | AK9: 0 | AL9: 1 | AM9: 15 | AN9: 15 | AO9: 13 | AP9: 14 | AQ9: 11 | AR9: 9 | AS9: 8 | AT9: 12 | AU9: 15 | AV9: 15 | AW9: 32 | AX9: 12 | AY9: 5 | AZ9: 5 | BA9: 2 | BB9: 1 | BC9: 0 | BD9: 0 | BE9: 0 | BF9: 2 | BG9: 59 | BH9: 3.2 | BI9: 3.0 - 4.0 | BJ9: 9 | BK9: 17 | BL9: 15 | BM9: 12 | BN9: 17 | BO9: 17 | BP9: 15 | BQ9: 17 | BR9: 12 | BS9: 10 | BT9: 32 | BU9: 15 | BV9: 7 | BW9: 5 | BX9: 0 | BY9: 2 | BZ9: 0 | CA9: 2 | CB9: 0 | CC9: 1 | CD9: 64 | CE9: 3.4 | CF9: 3.0 - 4.0 | CG9: W | CH9: 0.001409 | CI9: 3 | CJ9: 1 | CK9: 1 | CL9: <Null> | CM9: 461.94852 | CN9: 1 | CO9: 1 | CP9: <Null> | CQ9: <Null> | CR9: =IF(COUNTIF(Incl!A:A,Raw!J9),1, "")
A10: 7 | B10: 1 | C10: 195.74436 | D10: 7 | E10: 1 | F10: 36 | G10: 101 | H10: 101 | I10: 101 | J10: 101 | K10: El Camino Real | L10: Santa Clara Ave | M10: Santa Inez Ave | N10: NA | O10: NA | P10: 5 | Q10: NA | R10: NA | S10: NA | T10: 5 | U10: 1 | V10: 1 | W10: 4 | X10: NA | Y10: 20 | Z10: 20 | AA10: 82 | AB10: 0 | AC10: 1 | AD10: 4 | AE10: 2 | AF10: 7 | AG10: NA | AH10: 82 | AI10: 41 | AJ10: 143 | AK10: 0 | AL10: 2 | AM10: 1 | AN10: 2 | AO10: 2 | AP10: 1 | AQ10: 1 | AR10: 1 | AS10: 3 | AT10: 5 | AU10: 4 | AV10: 4 | AW10: 8 | AX10: 1 | AY10: 2 | AZ10: 0 | BA10: 0 | BB10: 0 | BC10: 0 | BD10: 1 | BE10: 0 | BF10: 0 | BG10: 12 | BH10: 2.4 | BI10: 2.0 - 3.0 | BJ10: 4 | BK10: 3 | BL10: 3 | BM10: 2 | BN10: 2 | BO10: 3 | BP10: 3 | BQ10: 5 | BR10: 7 | BS10: 6 | BT10: 3 | BU10: 7 | BV10: 2 | BW10: 0 | BX10: 1 | BY10: 0 | BZ10: 0 | CA10: 0 | CB10: 0 | CC10: 1 | CD10: 14 | CE10: 2.9 | CF10: 2.0 - 3.0 | CG10: E | CH10: 0.000596 | CI10: 3 | CJ10: <Null> | CK10: <Null> | CL10: <Null> | CM10: 195.7445 | CN10: 1 | CO10: 1 | CP10: <Null> | CQ10: <Null> | CR10: =IF(COUNTIF(Incl!A:A,Raw!J10),1, "")
A11: 8 | B11: 1 | C11: 198.9532 | D11: 8 | E11: 1 | F11: 37 | G11: 102 | H11: 102 | I11: 102 | J11: 102 | K11: El Camino Real | L11: San Diego Ave | M11: Santa Clara Ave | N11: NA | O11: 8 | P11: NA | Q11: NA | R11: NA | S11: NA | T11: 8 | U11: 1 | V11: 5 | W11: 8 | X11: NA | Y11: 12 | Z11: 60 | AA11: 95 | AB11: 0 | AC11: 1 | AD11: 0 | AE11: 1 | AF11: 7 | AG11: NA | AH11: 0 | AI11: 12 | AJ11: 83 | AK11: 0 | AL11: 1 | AM11: 1 | AN11: 3 | AO11: 5 | AP11: 5 | AQ11: 5 | AR11: 5 | AS11: 4 | AT11: 6 | AU11: 8 | AV11: 8 | AW11: 6 | AX11: 6 | AY11: 6 | AZ11: 0 | BA11: 1 | BB11: 0 | BC11: 0 | BD11: 0 | BE11: 1 | BF11: 0 | BG11: 20 | BH11: 2.4 | BI11: 2.0 - 3.0 | BJ11: 0 | BK11: 0 | BL11: 0 | BM11: 0 | BN11: 1 | BO11: 2 | BP11: 1 | BQ11: 3 | BR11: 7 | BS11: 7 | BT11: 7 | BU11: 4 | BV11: 2 | BW11: 0 | BX11: 0 | BY11: 0 | BZ11: 0 | CA11: 0 | CB11: 0 | CC11: 0 | CD11: 13 | CE11: 1.5 | CF11: 1.0 - 2.0 | CG11: E | CH11: 0.000609 | CI11: 2 | CJ11: <Null> | CK11: <Null> | CL11: <Null> | CM11: 198.9531 | CN11: 1 | CO11: 1 | CP11: <Null> | CQ11: <Null> | CR11: =IF(COUNTIF(Incl!A:A,Raw!J11),1, "")
A12: 9 | B12: 1 | C12: 205.77664 | D12: 9 | E12: 1 | F12: 38 | G12: 104 | H12: 104 | I12: 104 | J12: 104 | K12: El Camino Real | L12: Santa Maria Ave | M12: San Diego Ave | N12: NA | O12: 5 | P12: NA | Q12: NA | R12: NA | S12: NA | T12: 5 | U12: 3 | V12: 2 | W12: 2 | X12: NA | Y12: 59 | Z12: 39 | AA12: 39 | AB12: 0 | AC12: 0 | AD12: 2 | AE12: 2 | AF12: 3 | AG12: NA | AH12: 39 | AI12: 39 | AJ12: 59 | AK12: 0 | AL12: 0 | AM12: 3 | AN12: 1 | AO12: 1 | AP12: 1 | AQ12: 2 | AR12: 2 | AS12: 2 | AT12: 2 | AU12: 2 | AV12: 5 | AW12: 6 | AX12: 0 | AY12: 0 | AZ12: 0 | BA12: 1 | BB12: 0 | BC12: 0 | BD12: 0 | BE12: 0 | BF12: 1 | BG12: 8 | BH12: 1.6 | BI12: 1.0 - 2.0 | BJ12: 2 | BK12: 2 | BL12: 2 | BM12: 2 | BN12: 2 | BO12: 2 | BP12: 3 | BQ12: 4 | BR12: 3 | BS12: 3 | BT12: 0 | BU12: 1 | BV12: 1 | BW12: 0 | BX12: 0 | BY12: 0 | BZ12: 0 | CA12: 0 | CB12: 0 | CC12: 2 | CD12: 4 | CE12: 0.8 | CF12: 0.0 - 1.0 | CG12: E | CH12: 0.000623 | CI12: 0 | CJ12: <Null> | CK12: <Null> | CL12: <Null> | CM12: 205.77658 | CN12: 1 | CO12: 1 | CP12: <Null> | CQ12: <Null> | CR12: =IF(COUNTIF(Incl!A:A,Raw!J12),1, "")
A13: 10 | B13: 1 | C13: 76.880035 | D13: 10 | E13: 1 | F13: 39 | G13: 67 | H13: 67 | I13: 67 | J13: 67 | K13: Palmito Dr | L13: Park Blvd | M13: Alley | N13: NA | O13: NA | P13: 4 | Q13: NA | R13: NA | S13: NA | T13: 4 | U13: 3 | V13: 4 | W13: 4 | X13: 4 | Y13: 73 | Z13: 98 | AA13: 98 | AB13: 98 | AC13: 3 | AD13: 0 | AE13: 0 | AF13: 0 | AG13: 0 | AH13: 0 | AI13: 0 | AJ13: 0 | AK13: 0 | AL13: 0 | AM13: NA | AN13: NA | AO13: NA | AP13: NA | AQ13: NA | AR13: NA | AS13: NA | AT13: NA | AU13: NA | AV13: NA | AW13: NA | AX13: NA | AY13: NA | AZ13: NA | BA13: NA | BB13: NA | BC13: NA | BD13: NA | BE13: NA | BF13: NA | BG13: NA | BH13: NA | BI13: NA | BJ13: NA | BK13: NA | BL13: NA | BM13: NA | BN13: NA | BO13: NA | BP13: NA | BQ13: NA | BR13: NA | BS13: NA | BT13: NA | BU13: NA | BV13: NA | BW13: NA | BX13: NA | BY13: NA | BZ13: NA | CA13: NA | CB13: NA | CC13: NA | CD13: NA | CE13: NA | CF13: NA | CG13: W | CH13: 0.000212 | CI13: 3 | CJ13: <Null> | CK13: <Null> | CL13: <Null> | CM13: 76.880108 | CN13: 2 | CO13: 0 | CP13: <Null> | CQ13: <Null> | CR13: =IF(COUNTIF(Incl!A:A,Raw!J13),1, "")
A14: 11 | B14: 1 | C14: 64.002595 | D14: 11 | E14: 1 | F14: 40 | G14: 68 | H14: 68 | I14: 68 | J14: 68 | K14: Palmito Dr | L14: Alley | M14: Park Blvd | N14: NA | O14: NA | P14: NA | Q14: NA | R14: NA | S14: NA | T14: 0 | U14: 4 | V14: 4 | W14: 4 | X14: 4 | Y14: 0 | Z14: 0 | AA14: 0 | AB14: 0 | AC14: 0 | AD14: 4 | AE14: 4 | AF14: 4 | AG14: 0 | AH14: 0 | AI14: 0 | AJ14: 0 | AK14: 0 | AL14: 0 | AM14: NA | AN14: NA | AO14: NA | AP14: NA | AQ14: NA | AR14: NA | AS14: NA | AT14: NA | AU14: NA | AV14: NA | AW14: NA | AX14: NA | AY14: NA | AZ14: NA | BA14: NA | BB14: NA | BC14: NA | BD14: NA | BE14: NA | BF14: NA | BG14: NA | BH14: NA | BI14: NA | BJ14: NA | BK14: NA | BL14: NA | BM14: NA | BN14: NA | BO14: NA | BP14: NA | BQ14: NA | BR14: NA | BS14: NA | BT14: NA | BU14: NA | BV14: NA | BW14: NA | BX14: NA | BY14: NA | BZ14: NA | CA14: NA | CB14: NA | CC14: NA | CD14: NA | CE14: NA | CF14: NA | CG14: E | CH14: 0.000177 | CI14: 0 | CJ14: <Null> | CK14: <Null> | CL14: <Null> | CM14: 64.002649 | CN14: 2 | CO14: 0 | CP14: <Null> | CQ14: <Null> | CR14: =IF(COUNTIF(Incl!A:A,Raw!J14),1, "")
A15: 12 | B15: 1 | C15: 575.68186 | D15: 12 | E15: 1 | F15: 41 | G15: 69 | H15: 69 | I15: 69 | J15: 69 | K15: Palmito Dr | L15: Alley | M15: Capuchino Dr | N15: NA | O15: NA | P15: 19 | Q15: NA | R15: NA | S15: NA | T15: 19 | U15: 12 | V15: 12 | W15: 12 | X15: 13 | Y15: 63 | Z15: 63 | AA15: 63 | AB15: 68 | AC15: 0 | AD15: 12 | AE15: 11 | AF15: 10 | AG15: 10 | AH15: 63 | AI15: 58 | AJ15: 52 | AK15: 52 | AL15: 0 | AM15: NA | AN15: NA | AO15: NA | AP15: NA | AQ15: NA | AR15: NA | AS15: NA | AT15: NA | AU15: NA | AV15: NA | AW15: NA | AX15: NA | AY15: NA | AZ15: NA | BA15: NA | BB15: NA | BC15: NA | BD15: NA | BE15: NA | BF15: NA | BG15: NA | BH15: NA | BI15: NA | BJ15: NA | BK15: NA | BL15: NA | BM15: NA | BN15: NA | BO15: NA | BP15: NA | BQ15: NA | BR15: NA | BS15: NA | BT15: NA | BU15: NA | BV15: NA | BW15: NA | BX15: NA | BY15: NA | BZ15: NA | CA15: NA | CB15: NA | CC15: NA | CD15: NA | CE15: NA | CF15: NA | CG15: W | CH15: 0.001747 | CI15: 0 | CJ15: <Null> | CK15: <Null> | CL15: <Null> | CM15: 575.68193 | CN15: 2 | CO15: <Null> | CP15: <Null> | CQ15: <Null> | CR15: =IF(COUNTIF(Incl!A:A,Raw!J15),1, "")
A16: 13 | B16: 1 | C16: 568.53623 | D16: 13 | E16: 2 | F16: 42 | G16: 70 | H16: 70 | I16: 70 | J16: 70 | K16: Palmito Dr | L16: Capuchino Dr | M16: Alley | N16: NA | O16: NA | P16: 25 | Q16: NA | R16: NA | S16: NA | T16: 25 | U16: 17 | V16: 16 | W16: 15 | X16: 19 | Y16: 67 | Z16: 63 | AA16: 59 | AB16: 75 | AC16: 1 | AD16: 11 | AE16: 11 | AF16: 12 | AG16: 8 | AH16: 43 | AI16: 43 | AJ16: 47 | AK16: 31 | AL16: 0 | AM16: NA | AN16: NA | AO16: NA | AP16: NA | AQ16: NA | AR16: NA | AS16: NA | AT16: NA | AU16: NA | AV16: NA | AW16: NA | AX16: NA | AY16: NA | AZ16: NA | BA16: NA | BB16: NA | BC16: NA | BD16: NA | BE16: NA | BF16: NA | BG16: NA | BH16: NA | BI16: NA | BJ16: NA | BK16: NA | BL16: NA | BM16: NA | BN16: NA | BO16: NA | BP16: NA | BQ16: NA | BR16: NA | BS16: NA | BT16: NA | BU16: NA | BV16: NA | BW16: NA | BX16: NA | BY16: NA | BZ16: NA | CA16: NA | CB16: NA | CC16: NA | CD16: NA | CE16: NA | CF16: NA | CG16: E | CH16: 0.001731 | CI16: 1 | CJ16: <Null> | CK16: <Null> | CL16: <Null> | CM16: 568.53628 | CN16: 2 | CO16: <Null> | CP16: <Null> | CQ16: <Null> | CR16: =IF(COUNTIF(Incl!A:A,Raw!J16),1, "")
A17: 14 | B17: 1 | C17: 688.26173 | D17: 14 | E17: 4 | F17: 43 | G17: 99 | H17: 99 | I17: 99 | J17: 99 | K17: Alley | L17: Capuchino Dr | M17: Palmito Dr | N17: NA | O17: NA | P17: NA | Q17: NA | R17: NA | S17: NA | T17: 0 | U17: NA | V17: NA | W17: NA | X17: NA | Y17: 0 | Z17: 0 | AA17: 0 | AB17: 0 | AC17: 0 | AD17: 0 | AE17: 0 | AF17: 0 | AG17: 0 | AH17: 0 | AI17: 0 | AJ17: 0 | AK17: 0 | AL17: 0 | AM17: NA | AN17: NA | AO17: NA | AP17: NA | AQ17: NA | AR17: NA | AS17: NA | AT17: NA | AU17: NA | AV17: NA | AW17: NA | AX17: NA | AY17: NA | AZ17: NA | BA17: NA | BB17: NA | BC17: NA | BD17: NA | BE17: NA | BF17: NA | BG17: NA | BH17: NA | BI17: NA | BJ17: NA | BK17: NA | BL17: NA | BM17: NA | BN17: NA | BO17: NA | BP17: NA | BQ17: NA | BR17: NA | BS17: NA | BT17: NA | BU17: NA | BV17: NA | BW17: NA | BX17: NA | BY17: NA | BZ17: NA | CA17: NA | CB17: NA | CC17: NA | CD17: NA | CE17: NA | CF17: NA | CG17: E | CH17: 0.002148 | CI17: 0 | CJ17: <Null> | CK17: <Null> | CL17: <Null> | CM17: 688.26192 | CN17: 2 | CO17: <Null> | CP17: <Null> | CQ17: <Null> | CR17: =IF(COUNTIF(Incl!A:A,Raw!J17),1, "")
A18: 15 | B18: 1 | C18: 577.41561 | D18: 15 | E18: 3 | F18: 44 | G18: 98 | H18: 98 | I18: 98 | J18: 98 | K18: Alley | L18: Palmito Dr | M18: Capuchino Dr | N18: NA | O18: NA | P18: NA | Q18: NA | R18: NA | S18: NA | T18: 0 | U18: NA | V18: NA | W18: NA | X18: NA | Y18: 0 | Z18: 0 | AA18: 0 | AB18: 0 | AC18: 0 | AD18: 0 | AE18: 0 | AF18: 0 | AG18: 0 | AH18: 0 | AI18: 0 | AJ18: 0 | AK18: 0 | AL18: 0 | AM18: NA | AN18: NA | AO18: NA | AP18: NA | AQ18: NA | AR18: NA | AS18: NA | AT18: NA | AU18: NA | AV18: NA | AW18: NA | AX18: NA | AY18: NA | AZ18: NA | BA18: NA | BB18: NA | BC18: NA | BD18: NA | BE18: NA | BF18: NA | BG18: NA | BH18: NA | BI18: NA | BJ18: NA | BK18: NA | BL18: NA | BM18: NA | BN18: NA | BO18: NA | BP18: NA | BQ18: NA | BR18: NA | BS18: NA | BT18: NA | BU18: NA | BV18: NA | BW18: NA | BX18: NA | BY18: NA | BZ18: NA | CA18: NA | CB18: NA | CC18: NA | CD18: NA | CE18: NA | CF18: NA | CG18: W | CH18: 0.00179 | CI18: 0 | CJ18: <Null> | CK18: <Null> | CL18: <Null> | CM18: 577.41567 | CN18: 2 | CO18: <Null> | CP18: <Null> | CQ18: <Null> | CR18: =IF(COUNTIF(Incl!A:A,Raw!J18),1, "")
A19: 16 | B19: 1 | C19: 564.70664 | D19: 16 | E19: 2 | F19: 45 | G19: 103 | H19: 103 | I19: 103 | J19: 103 | K19: El Camino Real | L19: Park Blvd | M19: Capuchino Dr | N19: 1 | O19: 14 | P19: NA | Q19: NA | R19: NA | S19: NA | T19: 15 | U19: 7 | V19: 8 | W19: 7 | X19: NA | Y19: 47 | Z19: 54 | AA19: 47 | AB19: 0 | AC19: 0 | AD19: 7 | AE19: 7 | AF19: 12 | AG19: NA | AH19: 47 | AI19: 47 | AJ19: 81 | AK19: 0 | AL19: 1 | AM19: 7 | AN19: 6 | AO19: 7 | AP19: 6 | AQ19: 8 | AR19: 6 | AS19: 7 | AT19: 6 | AU19: 7 | AV19: 11 | AW19: 33 | AX19: 3 | AY19: 0 | AZ19: 0 | BA19: 0 | BB19: 0 | BC19: 1 | BD19: 1 | BE19: 2 | BF19: 0 | BG19: 40 | BH19: 2.7 | BI19: 2.0 - 3.0 | BJ19: 7 | BK19: 14 | BL19: 10 | BM19: 6 | BN19: 7 | BO19: 8 | BP19: 9 | BQ19: 10 | BR19: 12 | BS19: 12 | BT19: 48 | BU19: 9 | BV19: 6 | BW19: 0 | BX19: 1 | BY19: 1 | BZ19: 0 | CA19: 0 | CB19: 0 | CC19: 0 | CD19: 65 | CE19: 4.4 | CF19: 4.0 - 5.0 | CG19: W | CH19: 0.001717 | CI19: 1 | CJ19: 1 | CK19: 1 | CL19: <Null> | CM19: 564.70692 | CN19: 1 | CO19: 1 | CP19: <Null> | CQ19: <Null> | CR19: =IF(COUNTIF(Incl!A:A,Raw!J19),1, "")
A20: 17 | B20: 1 | C20: 235.88177 | D20: 17 | E20: 1 | F20: 46 | G20: 105 | H20: 105 | I20: 105 | J20: 105 | K20: El Camino Real | L20: Santa Helena Ave | M20: Santa Maria Ave | N20: NA | O20: 9 | P20: NA | Q20: NA | R20: NA | S20: NA | T20: 9 | U20: 1 | V20: 6 | W20: 2 | X20: NA | Y20: 11 | Z20: 64 | AA20: 21 | AB20: 0 | AC20: 0 | AD20: 3 | AE20: 1 | AF20: 5 | AG20: NA | AH20: 32 | AI20: 11 | AJ20: 53 | AK20: 0 | AL20: 0 | AM20: 1 | AN20: 2 | AO20: 2 | AP20: 3 | AQ20: 6 | AR20: 1 | AS20: 1 | AT20: 1 | AU20: 2 | AV20: 0 | AW20: 10 | AX20: 0 | AY20: 0 | AZ20: 1 | BA20: 1 | BB20: 0 | BC20: 0 | BD20: 0 | BE20: 0 | BF20: 0 | BG20: 12 | BH20: 1.3 | BI20: 1.0 - 2.0 | BJ20: 3 | BK20: 1 | BL20: 0 | BM20: 1 | BN20: 1 | BO20: 2 | BP20: 1 | BQ20: 1 | BR20: 5 | BS20: 2 | BT20: 8 | BU20: 1 | BV20: 1 | BW20: 1 | BX20: 0 | BY20: 0 | BZ20: 0 | CA20: 0 | CB20: 0 | CC20: 0 | CD20: 11 | CE20: 1.2 | CF20: 1.0 - 2.0 | CG20: E | CH20: 0.000714 | CI20: 0 | CJ20: <Null> | CK20: <Null> | CL20: <Null> | CM20: 235.88161 | CN20: 1 | CO20: 1 | CP20: <Null> | CQ20: <Null> | CR20: =IF(COUNTIF(Incl!A:A,Raw!J20),1, "")
A21: 18 | B21: 1 | C21: 237.92852 | D21: 18 | E21: 1 | F21: 47 | G21: 106 | H21: 106 | I21: 106 | J21: 106 | K21: El Camino Real | L21: San Juan Ave | M21: Santa Helena Ave | N21: NA | O21: 9 | P21: NA | Q21: NA | R21: NA | S21: NA | T21: 9 | U21: 7 | V21: 3 | W21: 3 | X21: NA | Y21: 74 | Z21: 32 | AA21: 32 | AB21: 0 | AC21: 0 | AD21: 2 | AE21: 4 | AF21: 7 | AG21: NA | AH21: 21 | AI21: 43 | AJ21: 74 | AK21: 0 | AL21: 0 | AM21: 7 | AN21: 7 | AO21: 4 | AP21: 3 | AQ21: 3 | AR21: 1 | AS21: 2 | AT21: 6 | AU21: 3 | AV21: 2 | AW21: 20 | AX21: 4 | AY21: 2 | AZ21: 1 | BA21: 0 | BB21: 0 | BC21: 0 | BD21: 0 | BE21: 0 | BF21: 0 | BG21: 27 | BH21: 2.9 | BI21: 2.0 - 3.0 | BJ21: 2 | BK21: 2 | BL21: 3 | BM21: 4 | BN21: 4 | BO21: 8 | BP21: 5 | BQ21: 7 | BR21: 7 | BS21: 0 | BT21: 16 | BU21: 5 | BV21: 2 | BW21: 1 | BX21: 0 | BY21: 1 | BZ21: 0 | CA21: 0 | CB21: 0 | CC21: 0 | CD21: 25 | CE21: 2.7 | CF21: 2.0 - 3.0 | CG21: E | CH21: 0.000723 | CI21: 0 | CJ21: <Null> | CK21: <Null> | CL21: <Null> | CM21: 237.92854 | CN21: 1 | CO21: 1 | CP21: <Null> | CQ21: <Null> | CR21: =IF(COUNTIF(Incl!A:A,Raw!J21),1, "")
A22: 19 | B22: 1 | C22: 51.271282 | D22: 19 | E22: 1 | F22: 48 | G22: 159 | H22: 159 | I22: 159 | J22: 159 | K22: Capuchino Dr | L22: Alley | M22: Palmito Dr | N22: NA | O22: NA | P22: 4 | Q22: NA | R22: NA | S22: NA | T22: 4 | U22: 2 | V22: 3 | W22: NA | X22: NA | Y22: 45 | Z22: 68 | AA22: 0 | AB22: 0 | AC22: 0 | AD22: 2 | AE22: 2 | AF22: 1 | AG22: NA | AH22: 45 | AI22: 45 | AJ22: 23 | AK22: 0 | AL22: 0 | AM22: 2 | AN22: 3 | AO22: 2 | AP22: 2 | AQ22: 3 | AR22: 2 | AS22: 2 | AT22: 0 | AU22: 0 | AV22: 0 | AW22: 1 | AX22: 0 | AY22: 1 | AZ22: 0 | BA22: 1 | BB22: 0 | BC22: 1 | BD22: 0 | BE22: 0 | BF22: 0 | BG22: 4 | BH22: 0.9 | BI22: 0.0 - 1.0 | BJ22: 2 | BK22: 2 | BL22: 1 | BM22: 2 | BN22: 2 | BO22: 3 | BP22: 2 | BQ22: 2 | BR22: 1 | BS22: 1 | BT22: 6 | BU22: 1 | BV22: 0 | BW22: 0 | BX22: 0 | BY22: 0 | BZ22: 0 | CA22: 0 | CB22: 0 | CC22: 1 | CD22: 8 | CE22: 1.8 | CF22: 1.0 - 2.0 | CG22: N | CH22: 0.000166 | CI22: 0 | CJ22: <Null> | CK22: <Null> | CL22: <Null> | CM22: 51.271182 | CN22: 1 | CO22: <Null> | CP22: <Null> | CQ22: <Null> | CR22: =IF(COUNTIF(Incl!A:A,Raw!J22),1, "")
A23: 20 | B23: 1 | C23: 51.362904 | D23: 20 | E23: 1 | F23: 49 | G23: 160 | H23: 160 | I23: 160 | J23: 160 | K23: Capuchino Dr | L23: El Camino Real | M23: Alley | N23: NA | O23: NA | P23: 2 | Q23: NA | R23: NA | S23: NA | T23: 2 | U23: 2 | V23: 2 | W23: 2 | X23: NA | Y23: 91 | Z23: 91 | AA23: 91 | AB23: 0 | AC23: 3 | AD23: 2 | AE23: 2 | AF23: 0 | AG23: NA | AH23: 91 | AI23: 91 | AJ23: 0 | AK23: 0 | AL23: 2 | AM23: 2 | AN23: 2 | AO23: 2 | AP23: 2 | AQ23: 2 | AR23: 2 | AS23: 2 | AT23: 2 | AU23: 2 | AV23: 2 | AW23: 0 | AX23: 0 | AY23: 0 | AZ23: 0 | BA23: 0 | BB23: 0 | BC23: 0 | BD23: 0 | BE23: 0 | BF23: 2 | BG23: 2 | BH23: 0.9 | BI23: 0.0 - 1.0 | BJ23: 2 | BK23: 2 | BL23: 2 | BM23: 2 | BN23: 2 | BO23: 2 | BP23: 1 | BQ23: 1 | BR23: 0 | BS23: 0 | BT23: 1 | BU23: 0 | BV23: 0 | BW23: 0 | BX23: 1 | BY23: 0 | BZ23: 0 | CA23: 1 | CB23: 0 | CC23: 0 | CD23: 3 | CE23: 1.4 | CF23: 1.0 - 2.0 | CG23: N | CH23: 0.000165 | CI23: 5 | CJ23: <Null> | CK23: <Null> | CL23: <Null> | CM23: 51.36282 | CN23: 1 | CO23: 0 | CP23: <Null> | CQ23: <Null> | CR23: =IF(COUNTIF(Incl!A:A,Raw!J23),1, "")
A24: 21 | B24: 1 | C24: 179.87375 | D24: 21 | E24: 2 | F24: 50 | G24: 161 | H24: 161 | I24: 161 | J24: 161 | K24: Capuchino Dr | L24: Palmito Dr | M24: El Camino Real | N24: NA | O24: NA | P24: 6 | Q24: NA | R24: NA | S24: NA | T24: 6 | U24: 1 | V24: 1 | W24: NA | X24: NA | Y24: 16 | Z24: 16 | AA24: 0 | AB24: 0 | AC24: 0 | AD24: 6 | AE24: 6 | AF24: 0 | AG24: NA | AH24: 94 | AI24: 94 | AJ24: 0 | AK24: 0 | AL24: 2 | AM24: 1 | AN24: 0 | AO24: 3 | AP24: 1 | AQ24: 1 | AR24: 3 | AS24: 1 | AT24: 0 | AU24: 0 | AV24: 0 | AW24: 5 | AX24: 1 | AY24: 1 | AZ24: 0 | BA24: 0 | BB24: 0 | BC24: 0 | BD24: 0 | BE24: 0 | BF24: 0 | BG24: 7 | BH24: 1.1 | BI24: 1.0 - 2.0 | BJ24: 6 | BK24: 5 | BL24: 3 | BM24: 6 | BN24: 6 | BO24: 4 | BP24: 4 | BQ24: 1 | BR24: 0 | BS24: 0 | BT24: 8 | BU24: 3 | BV24: 2 | BW24: 0 | BX24: 0 | BY24: 0 | BZ24: 1 | CA24: 1 | CB24: 0 | CC24: 0 | CD24: 15 | CE24: 2.3 | CF24: 2.0 - 3.0 | CG24: S | CH24: 0.000573 | CI24: 2 | CJ24: <Null> | CK24: <Null> | CL24: <Null> | CM24: 179.87379 | CN24: 1 | CO24: 0 | CP24: <Null> | CQ24: <Null> | CR24: =IF(COUNTIF(Incl!A:A,Raw!J24),1, "")
A25: 22 | B25: 1 | C25: 232.03311 | D25: 22 | E25: 1 | F25: 51 | G25: 71 | H25: 71 | I25: 71 | J25: 71 | K25: Broadway | L25: Capuchino Dr | M25: Millwood Dr | N25: NA | O25: NA | P25: 8 | Q25: NA | R25: NA | S25: NA | T25: 8 | U25: 8 | V25: 8 | W25: 8 | X25: 5 | Y25: 99 | Z25: 99 | AA25: 99 | AB25: 62 | AC25: 3 | AD25: 8 | AE25: 8 | AF25: 8 | AG25: 3 | AH25: 99 | AI25: 99 | AJ25: 99 | AK25: 37 | AL25: 3 | AM25: NA | AN25: NA | AO25: NA | AP25: NA | AQ25: NA | AR25: NA | AS25: NA | AT25: NA | AU25: NA | AV25: NA | AW25: NA | AX25: NA | AY25: NA | AZ25: NA | BA25: NA | BB25: NA | BC25: NA | BD25: NA | BE25: NA | BF25: NA | BG25: NA | BH25: NA | BI25: NA | BJ25: NA | BK25: NA | BL25: NA | BM25: NA | BN25: NA | BO25: NA | BP25: NA | BQ25: NA | BR25: NA | BS25: NA | BT25: NA | BU25: NA | BV25: NA | BW25: NA | BX25: NA | BY25: NA | BZ25: NA | CA25: NA | CB25: NA | CC25: NA | CD25: NA | CE25: NA | CF25: NA | CG25: W | CH25: 0.000694 | CI25: 6 | CJ25: <Null> | CK25: <Null> | CL25: <Null> | CM25: 232.03317 | CN25: 2 | CO25: <Null> | CP25: <Null> | CQ25: <Null> | CR25: =IF(COUNTIF(Incl!A:A,Raw!J25),1, "")
A26: 23 | B26: 1 | C26: 214.87336 | D26: 23 | E26: 1 | F26: 52 | G26: 72 | H26: 72 | I26: 72 | J26: 72 | K26: Broadway | L26: Millwood Dr | M26: Capuchino Dr | N26: NA | O26: NA | P26: 9 | Q26: NA | R26: NA | S26: NA | T26: 9 | U26: 8 | V26: 8 | W26: 8 | X26: 4 | Y26: 88 | Z26: 88 | AA26: 88 | AB26: 44 | AC26: 3 | AD26: 7 | AE26: 7 | AF26: 6 | AG26: 3 | AH26: 77 | AI26: 77 | AJ26: 66 | AK26: 33 | AL26: 2 | AM26: NA | AN26: NA | AO26: NA | AP26: NA | AQ26: NA | AR26: NA | AS26: NA | AT26: NA | AU26: NA | AV26: NA | AW26: NA | AX26: NA | AY26: NA | AZ26: NA | BA26: NA | BB26: NA | BC26: NA | BD26: NA | BE26: NA | BF26: NA | BG26: NA | BH26: NA | BI26: NA | BJ26: NA | BK26: NA | BL26: NA | BM26: NA | BN26: NA | BO26: NA | BP26: NA | BQ26: NA | BR26: NA | BS26: NA | BT26: NA | BU26: NA | BV26: NA | BW26: NA | BX26: NA | BY26: NA | BZ26: NA | CA26: NA | CB26: NA | CC26: NA | CD26: NA | CE26: NA | CF26: NA | CG26: E | CH26: 0.000654 | CI26: 5 | CJ26: <Null> | CK26: <Null> | CL26: <Null> | CM26: 214.87346 | CN26: 2 | CO26: <Null> | CP26: <Null> | CQ26: <Null> | CR26: =IF(COUNTIF(Incl!A:A,Raw!J26),1, "")
A27: 24 | B27: 1 | C27: 232.81606 | D27: 24 | E27: 1 | F27: 53 | G27: 107 | H27: 107 | I27: 107 | J27: 107 | K27: El Camino Real | L27: Capuchino Dr | M27: Millwood Dr | N27: 7 | O27: NA | P27: NA | Q27: NA | R27: NA | S27: NA | T27: 7 | U27: NA | V27: NA | W27: NA | X27: NA | Y27: 0 | Z27: 0 | AA27: 0 | AB27: 0 | AC27: 0 | AD27: 0 | AE27: 2 | AF27: 0 | AG27: NA | AH27: 0 | AI27: 28 | AJ27: 0 | AK27: 0 | AL27: 0 | AM27: 0 | AN27: 0 | AO27: 1 | AP27: 0 | AQ27: 0 | AR27: 0 | AS27: 0 | AT27: 0 | AU27: 0 | AV27: 0 | AW27: 1 | AX27: 0 | AY27: 0 | AZ27: 0 | BA27: 0 | BB27: 0 | BC27: 0 | BD27: 0 | BE27: 0 | BF27: 0 | BG27: 1 | BH27: 0.1 | BI27: 0.0 - 1.0 | BJ27: 0 | BK27: 0 | BL27: 0 | BM27: 0 | BN27: 2 | BO27: 0 | BP27: 2 | BQ27: 0 | BR27: 0 | BS27: 0 | BT27: 4 | BU27: 0 | BV27: 0 | BW27: 0 | BX27: 0 | BY27: 0 | BZ27: 0 | CA27: 0 | CB27: 0 | CC27: 0 | CD27: 4 | CE27: 0.6 | CF27: 0.0 - 1.0 | CG27: W | CH27: 0.000707 | CI27: 0 | CJ27: 1 | CK27: 1 | CL27: <Null> | CM27: 232.8159 | CN27: 1 | CO27: 1 | CP27: <Null> | CQ27: <Null> | CR27: =IF(COUNTIF(Incl!A:A,Raw!J27),1, "")
A28: 25 | B28: 1 | C28: 140.85674 | D28: 25 | E28: 1 | F28: 54 | G28: 162 | H28: 162 | I28: 162 | J28: 162 | K28: Milwood Dr | L28: El Camino Real | M28: Broadway | N28: NA | O28: NA | P28: 2 | Q28: NA | R28: NA | S28: NA | T28: 2 | U28: 2 | V28: NA | W28: NA | X28: NA | Y28: 114 | Z28: 0 | AA28: 0 | AB28: 0 | AC28: 1 | AD28: 0 | AE28: 1 | AF28: 0 | AG28: NA | AH28: 0 | AI28: 57 | AJ28: 0 | AK28: 0 | AL28: 0 | AM28: 2 | AN28: 2 | AO28: 2 | AP28: 2 | AQ28: 0 | AR28: 0 | AS28: 0 | AT28: 0 | AU28: 0 | AV28: 0 | AW28: 0 | AX28: 0 | AY28: 0 | AZ28: 2 | BA28: 0 | BB28: 0 | BC28: 0 | BD28: 0 | BE28: 0 | BF28: 0 | BG28: 2 | BH28: 1.1 | BI28: 1.0 - 2.0 | BJ28: 0 | BK28: 0 | BL28: 0 | BM28: 0 | BN28: 1 | BO28: 2 | BP28: 1 | BQ28: 0 | BR28: 0 | BS28: 0 | BT28: 2 | BU28: 1 | BV28: 0 | BW28: 0 | BX28: 0 | BY28: 0 | BZ28: 0 | CA28: 0 | CB28: 0 | CC28: 0 | CD28: 3 | CE28: 1.7 | CF28: 1.0 - 2.0 | CG28: N | CH28: 0.000462 | CI28: 1 | CJ28: <Null> | CK28: <Null> | CL28: <Null> | CM28: 140.85695 | CN28: 1 | CO28: 0 | CP28: <Null> | CQ28: <Null> | CR28: =IF(COUNTIF(Incl!A:A,Raw!J28),1, "")
A29: 26 | B29: 1 | C29: 159.55663 | D29: 26 | E29: 1 | F29: 55 | G29: 163 | H29: 163 | I29: 163 | J29: 163 | K29: Milwood Dr | L29: Broadway | M29: El Camino Real | N29: NA | O29: 6 | P29: NA | Q29: NA | R29: NA | S29: NA | T29: 6 | U29: 5 | V29: 1 | W29: 6 | X29: NA | Y29: 83 | Z29: 17 | AA29: 100 | AB29: 0 | AC29: 2 | AD29: 5 | AE29: 5 | AF29: 4 | AG29: NA | AH29: 83 | AI29: 83 | AJ29: 67 | AK29: 0 | AL29: 2 | AM29: 5 | AN29: 1 | AO29: 1 | AP29: 1 | AQ29: 1 | AR29: 3 | AS29: 5 | AT29: 5 | AU29: 6 | AV29: 1 | AW29: 10 | AX29: 6 | AY29: 1 | AZ29: 1 | BA29: 0 | BB29: 0 | BC29: 0 | BD29: 0 | BE29: 0 | BF29: 0 | BG29: 18 | BH29: 3 | BI29: 2.0 - 3.0 | BJ29: 5 | BK29: 6 | BL29: 6 | BM29: 3 | BN29: 5 | BO29: 4 | BP29: 6 | BQ29: 6 | BR29: 4 | BS29: 2 | BT29: 6 | BU29: 3 | BV29: 2 | BW29: 1 | BX29: 1 | BY29: 0 | BZ29: 0 | CA29: 0 | CB29: 0 | CC29: 2 | CD29: 15 | CE29: 2.5 | CF29: 2.0 - 3.0 | CG29: S | CH29: 0.000516 | CI29: 4 | CJ29: <Null> | CK29: <Null> | CL29: <Null> | CM29: 159.5566 | CN29: 1 | CO29: 0 | CP29: <Null> | CQ29: <Null> | CR29: =IF(COUNTIF(Incl!A:A,Raw!J29),1, "")
A30: 27 | B30: 1 | C30: 1292.5164 | D30: 27 | E30: 1 | F30: 56 | G30: 108 | H30: 108 | I30: 108 | J30: 108 | K30: El Camino Real | L30: Center St | M30: San Juan Ave | N30: 28 | O30: 8 | P30: NA | Q30: NA | R30: NA | S30: NA | T30: 35 | U30: 8 | V30: 18 | W30: 31 | X30: NA | Y30: 23 | Z30: 51 | AA30: 88 | AB30: 0 | AC30: 1 | AD30: 19 | AE30: 28 | AF30: 30 | AG30: NA | AH30: 54 | AI30: 79 | AJ30: 85 | AK30: 0 | AL30: 2 | AM30: 8 | AN30: 13 | AO30: 11 | AP30: 10 | AQ30: 18 | AR30: 26 | AS30: 27 | AT30: 30 | AU30: 31 | AV30: 28 | AW30: 58 | AX30: 24 | AY30: 6 | AZ30: 6 | BA30: 0 | BB30: 1 | BC30: 0 | BD30: 1 | BE30: 0 | BF30: 4 | BG30: 100 | BH30: 2.8 | BI30: 2.0 - 3.0 | BJ30: 19 | BK30: 26 | BL30: 32 | BM30: 29 | BN30: 28 | BO30: 27 | BP30: 26 | BQ30: 31 | BR30: 30 | BS30: 24 | BT30: 63 | BU30: 28 | BV30: 5 | BW30: 3 | BX30: 2 | BY30: 2 | BZ30: 0 | CA30: 2 | CB30: 2 | CC30: 7 | CD30: 114 | CE30: 3.2 | CF30: 3.0 - 4.0 | CG30: E | CH30: 0.003899 | CI30: 3 | CJ30: <Null> | CK30: <Null> | CL30: <Null> | CM30: 1292.5166 | CN30: 1 | CO30: 1 | CP30: <Null> | CQ30: <Null> | CR30: =IF(COUNTIF(Incl!A:A,Raw!J30),1, "")
A31: 28 | B31: 1 | C31: 765.64702 | D31: 28 | E31: 1 | F31: 57 | G31: 109 | H31: 109 | I31: 109 | J31: 109 | K31: El Camino Real | L31: Millwood Dr | M31: Ludeman Ln | N31: NA | O31: 26 | P31: NA | Q31: NA | R31: NA | S31: NA | T31: 26 | U31: 11 | V31: 11 | W31: 18 | X31: NA | Y31: 42 | Z31: 42 | AA31: 69 | AB31: 0 | AC31: 0 | AD31: 23 | AE31: 15 | AF31: 17 | AG31: NA | AH31: 89 | AI31: 58 | AJ31: 66 | AK31: 0 | AL31: 1 | AM31: 11 | AN31: 8 | AO31: 10 | AP31: 10 | AQ31: 11 | AR31: 18 | AS31: 12 | AT31: 12 | AU31: 18 | AV31: 19 | AW31: 26 | AX31: 8 | AY31: 5 | AZ31: 5 | BA31: 4 | BB31: 2 | BC31: 0 | BD31: 0 | BE31: 0 | BF31: 2 | BG31: 52 | BH31: 2 | BI31: 1.0 - 2.0 | BJ31: 23 | BK31: 21 | BL31: 22 | BM31: 15 | BN31: 15 | BO31: 10 | BP31: 13 | BQ31: 15 | BR31: 17 | BS31: 19 | BT31: 54 | BU31: 9 | BV31: 4 | BW31: 2 | BX31: 2 | BY31: 0 | BZ31: 3 | CA31: 1 | CB31: 1 | CC31: 3 | CD31: 79 | CE31: 3.1 | CF31: 3.0 - 4.0 | CG31: W | CH31: 0.00232 | CI31: 1 | CJ31: 1 | CK31: 1 | CL31: <Null> | CM31: 765.6471 | CN31: 1 | CO31: 1 | CP31: <Null> | CQ31: <Null> | CR31: =IF(COUNTIF(Incl!A:A,Raw!J31),1, "")
A32: 29 | B32: 1 | C32: 173.35116 | D32: 29 | E32: 1 | F32: 58 | G32: 73 | H32: 73 | I32: 73 | J32: 73 | K32: Broadway | L32: Millwood Dr | M32: Paramount Dr | N32: NA | O32: NA | P32: 8 | Q32: NA | R32: NA | S32: NA | T32: 8 | U32: 9 | V32: 4 | W32: 4 | X32: 4 | Y32: 117 | Z32: 52 | AA32: 52 | AB32: 52 | AC32: 1 | AD32: 5 | AE32: 5 | AF32: 3 | AG32: 4 | AH32: 65 | AI32: 65 | AJ32: 39 | AK32: 52 | AL32: 0 | AM32: NA | AN32: NA | AO32: NA | AP32: NA | AQ32: NA | AR32: NA | AS32: NA | AT32: NA | AU32: NA | AV32: NA | AW32: NA | AX32: NA | AY32: NA | AZ32: NA | BA32: NA | BB32: NA | BC32: NA | BD32: NA | BE32: NA | BF32: NA | BG32: NA | BH32: NA | BI32: NA | BJ32: NA | BK32: NA | BL32: NA | BM32: NA | BN32: NA | BO32: NA | BP32: NA | BQ32: NA | BR32: NA | BS32: NA | BT32: NA | BU32: NA | BV32: NA | BW32: NA | BX32: NA | BY32: NA | BZ32: NA | CA32: NA | CB32: NA | CC32: NA | CD32: NA | CE32: NA | CF32: NA | CG32: W | CH32: 0.00052 | CI32: 1 | CJ32: <Null> | CK32: <Null> | CL32: <Null> | CM32: 173.35113 | CN32: 2 | CO32: <Null> | CP32: <Null> | CQ32: <Null> | CR32: =IF(COUNTIF(Incl!A:A,Raw!J32),1, "")
A33: 30 | B33: 1 | C33: 545.14276 | D33: 30 | E33: 1 | F33: 59 | G33: 75 | H33: 75 | I33: 75 | J33: 75 | K33: Broadway | L33: Paramount Dr | M33: Ludeman Ln | N33: NA | O33: NA | P33: 18 | Q33: NA | R33: NA | S33: NA | T33: 18 | U33: 16 | V33: 16 | W33: 14 | X33: 16 | Y33: 90 | Z33: 90 | AA33: 79 | AB33: 90 | AC33: 4 | AD33: 18 | AE33: 16 | AF33: 18 | AG33: 17 | AH33: 101 | AI33: 90 | AJ33: 101 | AK33: 96 | AL33: 4 | AM33: NA | AN33: NA | AO33: NA | AP33: NA | AQ33: NA | AR33: NA | AS33: NA | AT33: NA | AU33: NA | AV33: NA | AW33: NA | AX33: NA | AY33: NA | AZ33: NA | BA33: NA | BB33: NA | BC33: NA | BD33: NA | BE33: NA | BF33: NA | BG33: NA | BH33: NA | BI33: NA | BJ33: NA | BK33: NA | BL33: NA | BM33: NA | BN33: NA | BO33: NA | BP33: NA | BQ33: NA | BR33: NA | BS33: NA | BT33: NA | BU33: NA | BV33: NA | BW33: NA | BX33: NA | BY33: NA | BZ33: NA | CA33: NA | CB33: NA | CC33: NA | CD33: NA | CE33: NA | CF33: NA | CG33: W | CH33: 0.001647 | CI33: 8 | CJ33: <Null> | CK33: <Null> | CL33: <Null> | CM33: 545.14294 | CN33: 2 | CO33: <Null> | CP33: <Null> | CQ33: <Null> | CR33: =IF(COUNTIF(Incl!A:A,Raw!J33),1, "")
A34: 31 | B34: 1 | C34: 750.15014 | D34: 31 | E34: 1 | F34: 60 | G34: 74 | H34: 74 | I34: 74 | J34: 74 | K34: Broadway | L34: Ludeman Ln | M34: Millwood Dr | N34: NA | O34: NA | P34: 28 | Q34: NA | R34: 1 | S34: NA | T34: 29 | U34: 27 | V34: 27 | W34: 25 | X34: 27 | Y34: 95 | Z34: 95 | AA34: 88 | AB34: 95 | AC34: 4 | AD34: 28 | AE34: 24 | AF34: 20 | AG34: 23 | AH34: 98 | AI34: 84 | AJ34: 70 | AK34: 81 | AL34: 3 | AM34: NA | AN34: NA | AO34: NA | AP34: NA | AQ34: NA | AR34: NA | AS34: NA | AT34: NA | AU34: NA | AV34: NA | AW34: NA | AX34: NA | AY34: NA | AZ34: NA | BA34: NA | BB34: NA | BC34: NA | BD34: NA | BE34: NA | BF34: NA | BG34: NA | BH34: NA | BI34: NA | BJ34: NA | BK34: NA | BL34: NA | BM34: NA | BN34: NA | BO34: NA | BP34: NA | BQ34: NA | BR34: NA | BS34: NA | BT34: NA | BU34: NA | BV34: NA | BW34: NA | BX34: NA | BY34: NA | BZ34: NA | CA34: NA | CB34: NA | CC34: NA | CD34: NA | CE34: NA | CF34: NA | CG34: E | CH34: 0.002279 | CI34: 7 | CJ34: <Null> | CK34: <Null> | CL34: <Null> | CM34: 750.15007 | CN34: 2 | CO34: <Null> | CP34: <Null> | CQ34: <Null> | CR34: =IF(COUNTIF(Incl!A:A,Raw!J34),1, "")
A35: 32 | B35: 1 | C35: 116.01234 | D35: 32 | E35: 1 | F35: 61 | G35: 164 | H35: 164 | I35: 164 | J35: 164 | K35: Ludeman Ln | L35: El Camino Real | M35: Broadway | N35: 6 | O35: NA | P35: NA | Q35: NA | R35: NA | S35: NA | T35: 6 | U35: 2 | V35: NA | W35: NA | X35: NA | Y35: 31 | Z35: 0 | AA35: 0 | AB35: 0 | AC35: 0 | AD35: 6 | AE35: 1 | AF35: 1 | AG35: NA | AH35: 94 | AI35: 16 | AJ35: 16 | AK35: 0 | AL35: 1 | AM35: 2 | AN35: 1 | AO35: 1 | AP35: 1 | AQ35: 0 | AR35: 0 | AS35: 0 | AT35: 0 | AU35: 0 | AV35: 0 | AW35: 3 | AX35: 1 | AY35: 0 | AZ35: 0 | BA35: 0 | BB35: 0 | BC35: 0 | BD35: 0 | BE35: 0 | BF35: 0 | BG35: 4 | BH35: 0.6 | BI35: 0.0 - 1.0 | BJ35: 6 | BK35: 6 | BL35: 6 | BM35: 1 | BN35: 1 | BO35: 1 | BP35: 1 | BQ35: 1 | BR35: 1 | BS35: 0 | BT35: 12 | BU35: 2 | BV35: 0 | BW35: 2 | BX35: 0 | BY35: 0 | BZ35: 0 | CA35: 0 | CB35: 0 | CC35: 0 | CD35: 16 | CE35: 2.5 | CF35: 2.0 - 3.0 | CG35: N | CH35: 0.000377 | CI35: 1 | CJ35: <Null> | CK35: <Null> | CL35: <Null> | CM35: 116.01234 | CN35: 1 | CO35: 0 | CP35: <Null> | CQ35: <Null> | CR35: =IF(COUNTIF(Incl!A:A,Raw!J35),1, "")
A36: 33 | B36: 1 | C36: 161.5132 | D36: 33 | E36: 1 | F36: 62 | G36: 165 | H36: 165 | I36: 165 | J36: 165 | K36: Ludeman Ln | L36: Broadway | M36: El Camino Real | N36: NA | O36: NA | P36: 7 | Q36: NA | R36: NA | S36: NA | T36: 7 | U36: 7 | V36: 5 | W36: 6 | X36: NA | Y36: 95 | Z36: 68 | AA36: 82 | AB36: 0 | AC36: 2 | AD36: 7 | AE36: 5 | AF36: 7 | AG36: NA | AH36: 95 | AI36: 68 | AJ36: 95 | AK36: 0 | AL36: 2 | AM36: 7 | AN36: 6 | AO36: 6 | AP36: 6 | AQ36: 5 | AR36: 5 | AS36: 6 | AT36: 5 | AU36: 6 | AV36: 6 | AW36: 5 | AX36: 4 | AY36: 1 | AZ36: 0 | BA36: 1 | BB36: 0 | BC36: 1 | BD36: 0 | BE36: 0 | BF36: 3 | BG36: 15 | BH36: 2 | BI36: 1.0 - 2.0 | BJ36: 7 | BK36: 7 | BL36: 7 | BM36: 5 | BN36: 5 | BO36: 5 | BP36: 6 | BQ36: 6 | BR36: 7 | BS36: 7 | BT36: 6 | BU36: 1 | BV36: 1 | BW36: 1 | BX36: 0 | BY36: 0 | BZ36: 1 | CA36: 0 | CB36: NA | CC36: 4 | CD36: 14 | CE36: 1.9 | CF36: 1.0 - 2.0 | CG36: S | CH36: 0.000442 | CI36: 4 | CJ36: 2 | CK36: <Null> | CL36: <Null> | CM36: 136.11984 | CN36: 1 | CO36: 0 | CP36: <Null> | CQ36: <Null> | CR36: =IF(COUNTIF(Incl!A:A,Raw!J36),1, "")
A37: 34 | B37: 1 | C37: 829.07106 | D37: 34 | E37: 1 | F37: 63 | G37: 76 | H37: 76 | I37: 76 | J37: 76 | K37: Broadway | L37: Ludeman Ln | M37: Parking Lot | N37: NA | O37: NA | P37: 15 | Q37: 2 | R37: 8 | S37: NA | T37: 25 | U37: 13 | V37: 15 | W37: 10 | X37: NA | Y37: 51 | Z37: 59 | AA37: 39 | AB37: 0 | AC37: 0 | AD37: 12 | AE37: 9 | AF37: 6 | AG37: NA | AH37: 47 | AI37: 35 | AJ37: 24 | AK37: 0 | AL37: 0 | AM37: 13 | AN37: 19 | AO37: 16 | AP37: 15 | AQ37: 15 | AR37: 17 | AS37: 21 | AT37: 21 | AU37: 10 | AV37: 9 | AW37: 54 | AX37: 19 | AY37: 0 | AZ37: 3 | BA37: 3 | BB37: 5 | BC37: 1 | BD37: 0 | BE37: 0 | BF37: 0 | BG37: 85 | BH37: 3.3 | BI37: 3.0 - 4.0 | BJ37: 12 | BK37: 12 | BL37: 13 | BM37: 9 | BN37: 9 | BO37: 7 | BP37: 6 | BQ37: 6 | BR37: 6 | BS37: 13 | BT37: 12 | BU37: 6 | BV37: 3 | BW37: 0 | BX37: 1 | BY37: 0 | BZ37: 0 | CA37: 2 | CB37: 1 | CC37: 3 | CD37: 28 | CE37: 1.1 | CF37: 1.0 - 2.0 | CG37: W | CH37: 0.002403 | CI37: 0 | CJ37: 4 | CK37: <Null> | CL37: <Null> | CM37: 791.03344 | CN37: 1 | CO37: <Null> | CP37: <Null> | CQ37: <Null> | CR37: =IF(COUNTIF(Incl!A:A,Raw!J37),1, "")
A38: 35 | B38: 1 | C38: 204.18013 | D38: 35 | E38: 1 | F38: 64 | G38: 77 | H38: 77 | I38: 77 | J38: 77 | K38: Broadway | L38: Center St | M38: Ludeman Ln | N38: NA | O38: NA | P38: 9 | Q38: NA | R38: NA | S38: NA | T38: 9 | U38: 9 | V38: 7 | W38: 4 | X38: NA | Y38: 96 | Z38: 74 | AA38: 43 | AB38: 0 | AC38: 1 | AD38: 8 | AE38: 8 | AF38: 4 | AG38: NA | AH38: 85 | AI38: 85 | AJ38: 43 | AK38: 0 | AL38: 2 | AM38: 9 | AN38: 9 | AO38: 9 | AP38: 8 | AQ38: 7 | AR38: 6 | AS38: 7 | AT38: 7 | AU38: 4 | AV38: 6 | AW38: 7 | AX38: 2 | AY38: 3 | AZ38: 1 | BA38: 2 | BB38: 0 | BC38: 0 | BD38: 0 | BE38: 2 | BF38: 2 | BG38: 19 | BH38: 2 | BI38: 1.0 - 2.0 | BJ38: 8 | BK38: 8 | BL38: 8 | BM38: 8 | BN38: 8 | BO38: 7 | BP38: 7 | BQ38: 4 | BR38: 4 | BS38: 4 | BT38: 4 | BU38: 1 | BV38: 0 | BW38: 1 | BX38: 3 | BY38: 0 | BZ38: 3 | CA38: 0 | CB38: 0 | CC38: 2 | CD38: 14 | CE38: 1.5 | CF38: 1.0 - 2.0 | CG38: E | CH38: 0.000624 | CI38: 3 | CJ38: 2 | CK38: <Null> | CL38: <Null> | CM38: 204.18016 | CN38: 1 | CO38: <Null> | CP38: <Null> | CQ38: <Null> | CR38: =IF(COUNTIF(Incl!A:A,Raw!J38),1, "")
A39: 36 | B39: 1 | C39: 865.18087 | D39: 36 | E39: 1 | F39: 65 | G39: 78 | H39: 78 | I39: 78 | J39: 78 | K39: Broadway | L39: Meadow Glen Ave | M39: Center St | N39: 6 | O39: 14 | P39: 10 | Q39: NA | R39: NA | S39: NA | T39: 30 | U39: 12 | V39: 12 | W39: 6 | X39: NA | Y39: 39 | Z39: 39 | AA39: 20 | AB39: 0 | AC39: 0 | AD39: 15 | AE39: 14 | AF39: 6 | AG39: NA | AH39: 49 | AI39: 46 | AJ39: 20 | AK39: 0 | AL39: 0 | AM39: 12 | AN39: 13 | AO39: 12 | AP39: 12 | AQ39: 12 | AR39: 12 | AS39: 12 | AT39: 19 | AU39: 6 | AV39: 7 | AW39: 53 | AX39: 2 | AY39: 2 | AZ39: 1 | BA39: 0 | BB39: 0 | BC39: 2 | BD39: 2 | BE39: 0 | BF39: 2 | BG39: 64 | BH39: 2.1 | BI39: 2.0 - 3.0 | BJ39: 15 | BK39: 9 | BL39: 15 | BM39: 11 | BN39: 14 | BO39: 14 | BP39: 13 | BQ39: 11 | BR39: 6 | BS39: 8 | BT39: 27 | BU39: 11 | BV39: 2 | BW39: 0 | BX39: 2 | BY39: 3 | BZ39: 1 | CA39: 2 | CB39: 0 | CC39: 1 | CD39: 49 | CE39: 1.6 | CF39: 1.0 - 2.0 | CG39: E | CH39: 0.002644 | CI39: 0 | CJ39: 2 | CK39: <Null> | CL39: <Null> | CM39: 865.18099 | CN39: 1 | CO39: <Null> | CP39: <Null> | CQ39: <Null> | CR39: =IF(COUNTIF(Incl!A:A,Raw!J39),1, "")
A40: 37 | B40: 1 | C40: 214.5328 | D40: 37 | E40: 1 | F40: 66 | G40: 110 | H40: 110 | I40: 110 | J40: 110 | K40: El Camino Real | L40: Ludeman Ln | M40: Center St | N40: NA | O40: 11 | P40: NA | Q40: NA | R40: NA | S40: NA | T40: 11 | U40: 1 | V40: NA | W40: 3 | X40: NA | Y40: 9 | Z40: 0 | AA40: 28 | AB40: 0 | AC40: 0 | AD40: 8 | AE40: 3 | AF40: 6 | AG40: NA | AH40: 74 | AI40: 28 | AJ40: 56 | AK40: 0 | AL40: 0 | AM40: 1 | AN40: 1 | AO40: 1 | AP40: 1 | AQ40: 0 | AR40: 0 | AS40: 0 | AT40: 2 | AU40: 3 | AV40: 10 | AW40: 8 | AX40: 2 | AY40: 1 | AZ40: 1 | BA40: 0 | BB40: 0 | BC40: 0 | BD40: 0 | BE40: 0 | BF40: 0 | BG40: 12 | BH40: 1.1 | BI40: 1.0 - 2.0 | BJ40: 8 | BK40: 9 | BL40: 10 | BM40: 3 | BN40: 3 | BO40: 3 | BP40: 3 | BQ40: 3 | BR40: 6 | BS40: 6 | BT40: 11 | BU40: 6 | BV40: 2 | BW40: 0 | BX40: 0 | BY40: 0 | BZ40: 1 | CA40: 1 | CB40: 0 | CC40: 1 | CD40: 22 | CE40: 2 | CF40: 2.0 - 3.0 | CG40: W | CH40: 0.000713 | CI40: 0 | CJ40: 1 | CK40: 1 | CL40: <Null> | CM40: 234.48701 | CN40: 1 | CO40: 1 | CP40: <Null> | CQ40: <Null> | CR40: =IF(COUNTIF(Incl!A:A,Raw!J40),1, "")
...

Sheet All
G1: Observations Where Occupancy > 75% | J1: Vehicles parking 1hr | L1: Turnover Rate | N1: Total Vehicles Count | P1: Total Vehicle Hours | X1: Hourly Chargeable Hours | Z1: Revenue | AD1: Hourly Chargeable Hours (w/ Reduction) | AF1: Revenue | AI1: Long-Term Vehicle Count | AK1: Revenue
A2: Segment | B2: Street | C2: From | D2: To | E2: Side | F2: Parking Supply | G2: Weekday | H2: Weekend | I2: Combined | J2: Weekday | K2: Weekend | L2: Weekday | M2: Weekend | N2: Weekday | O2: Weekend | P2: Weekday | Q2: Weekend | R2: Paid Parking Type | S2: 2-hr Parking | T2: 8-hr Parking | U2: Reduction | X2: Weekday | Y2: Weekend | Z2: Weekly | AA2: Annual | AC2: Supply | AD2: Weekday | AE2: Weekend | AF2: Weekly | AG2: Annual | AI2: Weekday | AJ2: Weekend | AK2: Weekly | AL2: Annual
A3: =Raw!J4 -> 154 | B3: =Raw!K4 -> Park Pl | C3: =Raw!L4 -> El Camino Real | D3: =Raw!M4 -> Park Blvd | E3: =Raw!CG4 -> N | F3: 8 | G3: =Raw!AL4 -> 1 | H3: =Raw!AC4 -> 1 | I3: =SUM(G3:H3) -> 2 | J3: =Raw!BT4 -> 13 | K3: =Raw!AW4 -> 25 | L3: =IF(Raw!CE4 = "NA", "-", Raw!CE4) -> 2 | M3: =IF(Raw!BH4 = "NA", "-", Raw!BH4) -> 2.9 | N3: 16 | O3: 23 | P3: 52 | Q3: 63 | R3: {=_xlfn.IFS(S3="YES", "Hourly", T3="YES", "Flat Rate")} -> Hourly | S3: =IF(Raw!CO4=1, "YES", "") -> YES | T3: =IF(Raw!CO4=2, "YES", "") | U3: =IF(Raw!CP4=1, "YES", "") | V3: Halved! | X3: 25 | Y3: 47 | Z3: =X3*5+Y3 -> 172 | AA3: =X3*261+Y3*52 -> 8969 | AC3: =IF(U3="YES", F3*0.6, F3) -> 8 | AD3: 25 | AE3: 47 | AF3: =AD3*5+AE3 -> 172 | AG3: =AD3*261+AE3*52 -> 8969 | AI3: =N3 -> 16 | AJ3: =O3 -> 23 | AK3: =(AI3*5+AJ3)*5.5 -> 566.5 | AL3: =(AI3*261+AJ3*52)*5.5 -> 29546
A4: =Raw!J5 -> 155 | B4: =Raw!K5 -> Park Pl | C4: =Raw!L5 -> Park Blvd | D4: =Raw!M5 -> El Camino Real | E4: =Raw!CG5 -> S | F4: 9 | G4: =Raw!AL5 -> 2 | H4: =Raw!AC5 -> 2 | I4: =SUM(G4:H4) -> 4 | J4: =Raw!BT5 -> 17 | K4: =Raw!AW5 -> 43 | L4: =IF(Raw!CE5 = "NA", "-", Raw!CE5) -> 2.3 | M4: =IF(Raw!BH5 = "NA", "-", Raw!BH5) -> 3.8 | N4: 20 | O4: 34 | P4: 67 | Q4: 77 | R4: {=_xlfn.IFS(S4="YES", "Hourly", T4="YES", "Flat Rate")} -> Hourly | S4: =IF(Raw!CO5=1, "YES", "") -> YES | T4: =IF(Raw!CO5=2, "YES", "") | U4: =IF(Raw!CP5=1, "YES", "") | V4: Halved! | X4: 32 | Y4: 61 | Z4: =X4*5+Y4 -> 221 | AA4: =X4*261+Y4*52 -> 11524 | AC4: =IF(U4="YES", F4*0.6, F4) -> 9 | AD4: 32 | AE4: 61 | AF4: =AD4*5+AE4 -> 221 | AG4: =AD4*261+AE4*52 -> 11524 | AI4: =N4 -> 20 | AJ4: =O4 -> 34 | AK4: =(AI4*5+AJ4)*5.5 -> 737 | AL4: =(AI4*261+AJ4*52)*5.5 -> 38434
A5: =Raw!J6 -> 156 | B5: =Raw!K6 -> Park Blvd | C5: =Raw!L6 -> Park Pl | D5: =Raw!M6 -> El Camino Real | E5: =Raw!CG6 -> N | F5: 12 | G5: =Raw!AL6 -> 0 | H5: =Raw!AC6 -> 2 | I5: =SUM(G5:H5) -> 2 | J5: =Raw!BT6 -> 19 | K5: =Raw!AW6 -> 82 | L5: =IF(Raw!CE6 = "NA", "-", Raw!CE6) -> 1.7 | M5: =IF(Raw!BH6 = "NA", "-", Raw!BH6) -> 4.4 | N5: 21 | O5: 55 | P5: 61 | Q5: 92 | R5: {=_xlfn.IFS(S5="YES", "Hourly", T5="YES", "Flat Rate")} -> Hourly | S5: =IF(Raw!CO6=1, "YES", "") -> YES | T5: =IF(Raw!CO6=2, "YES", "") | U5: =IF(Raw!CP6=1, "YES", "") | V5: Halved! | X5: 33 | Y5: 61 | Z5: =X5*5+Y5 -> 226 | AA5: =X5*261+Y5*52 -> 11785 | AC5: =IF(U5="YES", F5*0.6, F5) -> 12 | AD5: 33 | AE5: 61 | AF5: =AD5*5+AE5 -> 226 | AG5: =AD5*261+AE5*52 -> 11785 | AI5: =N5 -> 21 | AJ5: =O5 -> 55 | AK5: =(AI5*5+AJ5)*5.5 -> 880 | AL5: =(AI5*261+AJ5*52)*5.5 -> 45875.5
A6: =Raw!J7 -> 157 | B6: =Raw!K7 -> Park Blvd | C6: =Raw!L7 -> Magnolia Ave | D6: =Raw!M7 -> Palmito Dr | E6: =Raw!CG7 -> S | F6: =Raw!T7 -> 14 | G6: =Raw!AL7 -> 4 | H6: =Raw!AC7 -> 0 | I6: =SUM(G6:H6) -> 4 | J6: =Raw!BT7 -> NA | K6: =Raw!AW7 -> NA | L6: =IF(Raw!CE7 = "NA", "-", Raw!CE7) -> - | M6: =IF(Raw!BH7 = "NA", "-", Raw!BH7) -> - | N6: =IF(Raw!CD7 = "NA", "-", Raw!CD7) -> - | O6: =IF(Raw!BG7 = "NA", "-", Raw!BG7) -> - | P6: =IF(Raw!AW7 = "NA", "-", SUMPRODUCT(Raw!$BT$2:$CC$2, Raw!BT7:CC7)) -> - | Q6: =IF(Raw!AW7 = "NA", "-", SUMPRODUCT(Raw!$AW$2:$BF$2, Raw!AW7:BF7)) -> - | R6: {=_xlfn.IFS(S6="YES", "Hourly", T6="YES", "Flat Rate")} -> #N/A | S6: =IF(Raw!CO7=1, "YES", "") | T6: =IF(Raw!CO7=2, "YES", "") | U6: =IF(Raw!CP7=1, "YES", "") | X6: =SUMPRODUCT(Raw!$BT$3:$CC$3, Raw!BT7:CC7) -> 0 | Y6: =SUMPRODUCT(Raw!$BT$3:$CC$3, Raw!BU7:CD7) -> 0 | Z6: =X6*5+Y6 -> 0 | AA6: =X6*261+Y6*52 -> 0 | AC6: =IF(U6="YES", F6*0.6, F6) -> 14 | AD6: =IF(U6="YES",SUMPRODUCT(Raw!$BT$3:$CC$3,Raw!BT7:CC7)*0.6,SUMPRODUCT(Raw!$BT$3:$CC$3,Raw!BT7:CC7)) -> 0 | AE6: =IF(U6="YES",SUMPRODUCT(Raw!$BT$3:$CC$3,Raw!BU7:CD7)*0.6,SUMPRODUCT(Raw!$BT$3:$CC$3,Raw!BU7:CD7)) -> 0 | AF6: =AD6*5+AE6 -> 0 | AG6: =AD6*261+AE6*52 -> 0 | AI6: =N6 -> - | AJ6: =O6 -> - | AK6: =(AI6*5+AJ6)*5.5 -> #VALUE! | AL6: =(AI6*261+AJ6*52)*5.5 -> #VALUE!
A7: =Raw!J8 -> 158 | B7: =Raw!K8 -> Park Blvd | C7: =Raw!L8 -> Palmito Dr | D7: =Raw!M8 -> El Camino Real | E7: =Raw!CG8 -> S | F7: =Raw!T8 -> 11 | G7: =Raw!AL8 -> 0 | H7: =Raw!AC8 -> 1 | I7: =SUM(G7:H7) -> 1 | J7: =Raw!BT8 -> 11 | K7: =Raw!AW8 -> 39 | L7: =IF(Raw!CE8 = "NA", "-", Raw!CE8) -> 1.6 | M7: =IF(Raw!BH8 = "NA", "-", Raw!BH8) -> 4.5 | N7: =IF(Raw!CD8 = "NA", "-", Raw!CD8) -> 18 | O7: =IF(Raw!BG8 = "NA", "-", Raw!BG8) -> 50 | P7: =IF(Raw!AW8 = "NA", "-", SUMPRODUCT(Raw!$BT$2:$CC$2, Raw!BT8:CC8)) -> 41 | Q7: =IF(Raw!AW8 = "NA", "-", SUMPRODUCT(Raw!$AW$2:$BF$2, Raw!AW8:BF8)) -> 71 | R7: {=_xlfn.IFS(S7="YES", "Hourly", T7="YES", "Flat Rate")} -> Hourly | S7: =IF(Raw!CO8=1, "YES", "") -> YES | T7: =IF(Raw!CO8=2, "YES", "") | U7: =IF(Raw!CP8=1, "YES", "") | X7: =SUMPRODUCT(Raw!$BT$3:$CC$3, Raw!BT8:CC8) -> 25 | Y7: =SUMPRODUCT(Raw!$BT$3:$CC$3, Raw!BU8:CD8) -> 49 | Z7: =X7*5+Y7 -> 174 | AA7: =X7*261+Y7*52 -> 9073 | AC7: =IF(U7="YES", F7*0.6, F7) -> 11 | AD7: =IF(U7="YES",SUMPRODUCT(Raw!$BT$3:$CC$3,Raw!BT8:CC8)*0.6,SUMPRODUCT(Raw!$BT$3:$CC$3,Raw!BT8:CC8)) -> 25 | AE7: =IF(U7="YES",SUMPRODUCT(Raw!$BT$3:$CC$3,Raw!BU8:CD8)*0.6,SUMPRODUCT(Raw!$BT$3:$CC$3,Raw!BU8:CD8)) -> 49 | AF7: =AD7*5+AE7 -> 174 | AG7: =AD7*261+AE7*52 -> 9073 | AI7: =N7 -> 18 | AJ7: =O7 -> 50 | AK7: =(AI7*5+AJ7)*5.5 -> 770 | AL7: =(AI7*261+AJ7*52)*5.5 -> 40139
A8: =Raw!J9 -> 100 | B8: =Raw!K9 -> El Camino Real | C8: =Raw!L9 -> Park Pl | D8: =Raw!M9 -> Park Blvd | E8: =Raw!CG9 -> W | F8: =Raw!T9 -> 19 | G8: =Raw!AL9 -> 1 | H8: =Raw!AC9 -> 2 | I8: =SUM(G8:H8) -> 3 | J8: =Raw!BT9 -> 32 | K8: =Raw!AW9 -> 32 | L8: =IF(Raw!CE9 = "NA", "-", Raw!CE9) -> 3.4 | M8: =IF(Raw!BH9 = "NA", "-", Raw!BH9) -> 3.2 | N8: =IF(Raw!CD9 = "NA", "-", Raw!CD9) -> 64 | O8: =IF(Raw!BG9 = "NA", "-", Raw!BG9) -> 59 | P8: =IF(Raw!AW9 = "NA", "-", SUMPRODUCT(Raw!$BT$2:$CC$2, Raw!BT9:CC9)) -> 141 | Q8: =IF(Raw!AW9 = "NA", "-", SUMPRODUCT(Raw!$AW$2:$BF$2, Raw!AW9:BF9)) -> 127 | R8: {=_xlfn.IFS(S8="YES", "Hourly", T8="YES", "Flat Rate")} -> Hourly | S8: =IF(Raw!CO9=1, "YES", "") -> YES | T8: =IF(Raw!CO9=2, "YES", "") | U8: =IF(Raw!CP9=1, "YES", "") | X8: =SUMPRODUCT(Raw!$BT$3:$CC$3, Raw!BT9:CC9) -> 96 | Y8: =SUMPRODUCT(Raw!$BT$3:$CC$3, Raw!BU9:CD9) -> 177 | Z8: =X8*5+Y8 -> 657 | AA8: =X8*261+Y8*52 -> 34260 | AC8: =IF(U8="YES", F8*0.6, F8) -> 19 | AD8: =IF(U8="YES",SUMPRODUCT(Raw!$BT$3:$CC$3,Raw!BT9:CC9)*0.6,SUMPRODUCT(Raw!$BT$3:$CC$3,Raw!BT9:CC9)) -> 96 | AE8: =IF(U8="YES",SUMPRODUCT(Raw!$BT$3:$CC$3,Raw!BU9:CD9)*0.6,SUMPRODUCT(Raw!$BT$3:$CC$3,Raw!BU9:CD9)) -> 177 | AF8: =AD8*5+AE8 -> 657 | AG8: =AD8*261+AE8*52 -> 34260 | AI8: =N8 -> 64 | AJ8: =O8 -> 59 | AK8: =(AI8*5+AJ8)*5.5 -> 2084.5 | AL8: =(AI8*261+AJ8*52)*5.5 -> 108746
A9: =Raw!J10 -> 101 | B9: =Raw!K10 -> El Camino Real | C9: =Raw!L10 -> Santa Clara Ave | D9: =Raw!M10 -> Santa Inez Ave | E9: =Raw!CG10 -> E | F9: =Raw!T10 -> 5 | G9: =Raw!AL10 -> 2 | H9: =Raw!AC10 -> 1 | I9: =SUM(G9:H9) -> 3 | J9: =Raw!BT10 -> 3 | K9: =Raw!AW10 -> 8 | L9: =IF(Raw!CE10 = "NA", "-", Raw!CE10) -> 2.9 | M9: =IF(Raw!BH10 = "NA", "-", Raw!BH10) -> 2.4 | N9: =IF(Raw!CD10 = "NA", "-", Raw!CD10) -> 14 | O9: =IF(Raw!BG10 = "NA", "-", Raw!BG10) -> 12 | P9: =IF(Raw!AW10 = "NA", "-", SUMPRODUCT(Raw!$BT$2:$CC$2, Raw!BT10:CC10)) -> 38 | Q9: =IF(Raw!AW10 = "NA", "-", SUMPRODUCT(Raw!$AW$2:$BF$2, Raw!AW10:BF10)) -> 24 | R9: {=_xlfn.IFS(S9="YES", "Hourly", T9="YES", "Flat Rate")} -> Hourly | S9: =IF(Raw!CO10=1, "YES", "") -> YES | T9: =IF(Raw!CO10=2, "YES", "") | U9: =IF(Raw!CP10=1, "YES", "") | X9: =SUMPRODUCT(Raw!$BT$3:$CC$3, Raw!BT10:CC10) -> 25 | Y9: =SUMPRODUCT(Raw!$BT$3:$CC$3, Raw!BU10:CD10) -> 43 | Z9: =X9*5+Y9 -> 168 | AA9: =X9*261+Y9*52 -> 8761 | AC9: =IF(U9="YES", F9*0.6, F9) -> 5 | AD9: =IF(U9="YES",SUMPRODUCT(Raw!$BT$3:$CC$3,Raw!BT10:CC10)*0.6,SUMPRODUCT(Raw!$BT$3:$CC$3,Raw!BT10:CC10)) -> 25 | AE9: =IF(U9="YES",SUMPRODUCT(Raw!$BT$3:$CC$3,Raw!BU10:CD10)*0.6,SUMPRODUCT(Raw!$BT$3:$CC$3,Raw!BU10:CD10)) -> 43 | AF9: =AD9*5+AE9 -> 168 | AG9: =AD9*261+AE9*52 -> 8761 | AI9: =N9 -> 14 | AJ9: =O9 -> 12 | AK9: =(AI9*5+AJ9)*5.5 -> 451 | AL9: =(AI9*261+AJ9*52)*5.5 -> 23529
A10: =Raw!J11 -> 102 | B10: =Raw!K11 -> El Camino Real | C10: =Raw!L11 -> San Diego Ave | D10: =Raw!M11 -> Santa Clara Ave | E10: =Raw!CG11 -> E | F10: =Raw!T11 -> 8 | G10: =Raw!AL11 -> 1 | H10: =Raw!AC11 -> 1 | I10: =SUM(G10:H10) -> 2 | J10: =Raw!BT11 -> 7 | K10: =Raw!AW11 -> 6 | L10: =IF(Raw!CE11 = "NA", "-", Raw!CE11) -> 1.5 | M10: =IF(Raw!BH11 = "NA", "-", Raw!BH11) -> 2.4 | N10: =IF(Raw!CD11 = "NA", "-", Raw!CD11) -> 13 | O10: =IF(Raw!BG11 = "NA", "-", Raw!BG11) -> 20 | P10: =IF(Raw!AW11 = "NA", "-", SUMPRODUCT(Raw!$BT$2:$CC$2, Raw!BT11:CC11)) -> 21 | Q10: =IF(Raw!AW11 = "NA", "-", SUMPRODUCT(Raw!$AW$2:$BF$2, Raw!AW11:BF11)) -> 50 | R10: {=_xlfn.IFS(S10="YES", "Hourly", T10="YES", "Flat Rate")} -> Hourly | S10: =IF(Raw!CO11=1, "YES", "") -> YES | T10: =IF(Raw!CO11=2, "YES", "") | U10: =IF(Raw!CP11=1, "YES", "") | X10: =SUMPRODUCT(Raw!$BT$3:$CC$3, Raw!BT11:CC11) -> 19 | Y10: =SUMPRODUCT(Raw!$BT$3:$CC$3, Raw!BU11:CD11) -> 34 | Z10: =X10*5+Y10 -> 129 | AA10: =X10*261+Y10*52 -> 6727 | AC10: =IF(U10="YES", F10*0.6, F10) -> 8 | AD10: =IF(U10="YES",SUMPRODUCT(Raw!$BT$3:$CC$3,Raw!BT11:CC11)*0.6,SUMPRODUCT(Raw!$BT$3:$CC$3,Raw!BT11:CC11)) -> 19 | AE10: =IF(U10="YES",SUMPRODUCT(Raw!$BT$3:$CC$3,Raw!BU11:CD11)*0.6,SUMPRODUCT(Raw!$BT$3:$CC$3,Raw!BU11:CD11)) -> 34 | AF10: =AD10*5+AE10 -> 129 | AG10: =AD10*261+AE10*52 -> 6727 | AI10: =N10 -> 13 | AJ10: =O10 -> 20 | AK10: =(AI10*5+AJ10)*5.5 -> 467.5 | AL10: =(AI10*261+AJ10*52)*5.5 -> 24381.5
A11: =Raw!J12 -> 104 | B11: =Raw!K12 -> El Camino Real | C11: =Raw!L12 -> Santa Maria Ave | D11: =Raw!M12 -> San Diego Ave | E11: =Raw!CG12 -> E | F11: =Raw!T12 -> 5 | G11: =Raw!AL12 -> 0 | H11: =Raw!AC12 -> 0 | I11: =SUM(G11:H11) -> 0 | J11: =Raw!BT12 -> 0 | K11: =Raw!AW12 -> 6 | L11: =IF(Raw!CE12 = "NA", "-", Raw!CE12) -> 0.8 | M11: =IF(Raw!BH12 = "NA", "-", Raw!BH12) -> 1.6 | N11: =IF(Raw!CD12 = "NA", "-", Raw!CD12) -> 4 | O11: =IF(Raw!BG12 = "NA", "-", Raw!BG12) -> 8 | P11: =IF(Raw!AW12 = "NA", "-", SUMPRODUCT(Raw!$BT$2:$CC$2, Raw!BT12:CC12)) -> 25 | Q11: =IF(Raw!AW12 = "NA", "-", SUMPRODUCT(Raw!$AW$2:$BF$2, Raw!AW12:BF12)) -> 21 | R11: {=_xlfn.IFS(S11="YES", "Hourly", T11="YES", "Flat Rate")} -> Hourly | S11: =IF(Raw!CO12=1, "YES", "") -> YES | T11: =IF(Raw!CO12=2, "YES", "") | U11: =IF(Raw!CP12=1, "YES", "") | X11: =SUMPRODUCT(Raw!$BT$3:$CC$3, Raw!BT12:CC12) -> 8 | Y11: =SUMPRODUCT(Raw!$BT$3:$CC$3, Raw!BU12:CD12) -> 15 | Z11: =X11*5+Y11 -> 55 | AA11: =X11*261+Y11*52 -> 2868 | AC11: =IF(U11="YES", F11*0.6, F11) -> 5 | AD11: =IF(U11="YES",SUMPRODUCT(Raw!$BT$3:$CC$3,Raw!BT12:CC12)*0.6,SUMPRODUCT(Raw!$BT$3:$CC$3,Raw!BT12:CC12)) -> 8 | AE11: =IF(U11="YES",SUMPRODUCT(Raw!$BT$3:$CC$3,Raw!BU12:CD12)*0.6,SUMPRODUCT(Raw!$BT$3:$CC$3,Raw!BU12:CD12)) -> 15 | AF11: =AD11*5+AE11 -> 55 | AG11: =AD11*261+AE11*52 -> 2868 | AI11: =N11 -> 4 | AJ11: =O11 -> 8 | AK11: =(AI11*5+AJ11)*5.5 -> 154 | AL11: =(AI11*261+AJ11*52)*5.5 -> 8030
A12: =Raw!J13 -> 67 | B12: =Raw!K13 -> Palmito Dr | C12: =Raw!L13 -> Park Blvd | D12: =Raw!M13 -> Alley | E12: =Raw!CG13 -> W | F12: =Raw!T13 -> 4 | G12: =Raw!AL13 -> 0 | H12: =Raw!AC13 -> 3 | I12: =SUM(G12:H12) -> 3 | J12: =Raw!BT13 -> NA | K12: =Raw!AW13 -> NA | L12: =IF(Raw!CE13 = "NA", "-", Raw!CE13) -> - | M12: =IF(Raw!BH13 = "NA", "-", Raw!BH13) -> - | N12: =IF(Raw!CD13 = "NA", "-", Raw!CD13) -> - | O12: =IF(Raw!BG13 = "NA", "-", Raw!BG13) -> - | P12: =IF(Raw!AW13 = "NA", "-", SUMPRODUCT(Raw!$BT$2:$CC$2, Raw!BT13:CC13)) -> - | Q12: =IF(Raw!AW13 = "NA", "-", SUMPRODUCT(Raw!$AW$2:$BF$2, Raw!AW13:BF13)) -> - | R12: {=_xlfn.IFS(S12="YES", "Hourly", T12="YES", "Flat Rate")} -> #N/A | S12: =IF(Raw!CO13=1, "YES", "") | T12: =IF(Raw!CO13=2, "YES", "") | U12: =IF(Raw!CP13=1, "YES", "") | X12: =SUMPRODUCT(Raw!$BT$3:$CC$3, Raw!BT13:CC13) -> 0 | Y12: =SUMPRODUCT(Raw!$BT$3:$CC$3, Raw!BU13:CD13) -> 0 | Z12: =X12*5+Y12 -> 0 | AA12: =X12*261+Y12*52 -> 0 | AC12: =IF(U12="YES", F12*0.6, F12) -> 4 | AD12: =IF(U12="YES",SUMPRODUCT(Raw!$BT$3:$CC$3,Raw!BT13:CC13)*0.6,SUMPRODUCT(Raw!$BT$3:$CC$3,Raw!BT13:CC13)) -> 0 | AE12: =IF(U12="YES",SUMPRODUCT(Raw!$BT$3:$CC$3,Raw!BU13:CD13)*0.6,SUMPRODUCT(Raw!$BT$3:$CC$3,Raw!BU13:CD13)) -> 0 | AF12: =AD12*5+AE12 -> 0 | AG12: =AD12*261+AE12*52 -> 0 | AI12: =N12 -> - | AJ12: =O12 -> - | AK12: =(AI12*5+AJ12)*5.5 -> #VALUE! | AL12: =(AI12*261+AJ12*52)*5.5 -> #VALUE!
A13: =Raw!J14 -> 68 | B13: =Raw!K14 -> Palmito Dr | C13: =Raw!L14 -> Alley | D13: =Raw!M14 -> Park Blvd | E13: =Raw!CG14 -> E | F13: =Raw!T14 -> 0 | G13: =Raw!AL14 -> 0 | H13: =Raw!AC14 -> 0 | I13: =SUM(G13:H13) -> 0 | J13: =Raw!BT14 -> NA | K13: =Raw!AW14 -> NA | L13: =IF(Raw!CE14 = "NA", "-", Raw!CE14) -> - | M13: =IF(Raw!BH14 = "NA", "-", Raw!BH14) -> - | N13: =IF(Raw!CD14 = "NA", "-", Raw!CD14) -> - | O13: =IF(Raw!BG14 = "NA", "-", Raw!BG14) -> - | P13: =IF(Raw!AW14 = "NA", "-", SUMPRODUCT(Raw!$BT$2:$CC$2, Raw!BT14:CC14)) -> - | Q13: =IF(Raw!AW14 = "NA", "-", SUMPRODUCT(Raw!$AW$2:$BF$2, Raw!AW14:BF14)) -> - | R13: {=_xlfn.IFS(S13="YES", "Hourly", T13="YES", "Flat Rate")} -> #N/A | S13: =IF(Raw!CO14=1, "YES", "") | T13: =IF(Raw!CO14=2, "YES", "") | U13: =IF(Raw!CP14=1, "YES", "") | X13: =SUMPRODUCT(Raw!$BT$3:$CC$3, Raw!BT14:CC14) -> 0 | Y13: =SUMPRODUCT(Raw!$BT$3:$CC$3, Raw!BU14:CD14) -> 0 | Z13: =X13*5+Y13 -> 0 | AA13: =X13*261+Y13*52 -> 0 | AC13: =IF(U13="YES", F13*0.6, F13) -> 0 | AD13: =IF(U13="YES",SUMPRODUCT(Raw!$BT$3:$CC$3,Raw!BT14:CC14)*0.6,SUMPRODUCT(Raw!$BT$3:$CC$3,Raw!BT14:CC14)) -> 0 | AE13: =IF(U13="YES",SUMPRODUCT(Raw!$BT$3:$CC$3,Raw!BU14:CD14)*0.6,SUMPRODUCT(Raw!$BT$3:$CC$3,Raw!BU14:CD14)) -> 0 | AF13: =AD13*5+AE13 -> 0 | AG13: =AD13*261+AE13*52 -> 0 | AI13: =N13 -> - | AJ13: =O13 -> - | AK13: =(AI13*5+AJ13)*5.5 -> #VALUE! | AL13: =(AI13*261+AJ13*52)*5.5 -> #VALUE!
A14: =Raw!J15 -> 69 | B14: =Raw!K15 -> Palmito Dr | C14: =Raw!L15 -> Alley | D14: =Raw!M15 -> Capuchino Dr | E14: =Raw!CG15 -> W | F14: =Raw!T15 -> 19 | G14: =Raw!AL15 -> 0 | H14: =Raw!AC15 -> 0 | I14: =SUM(G14:H14) -> 0 | J14: =Raw!BT15 -> NA | K14: =Raw!AW15 -> NA | L14: =IF(Raw!CE15 = "NA", "-", Raw!CE15) -> - | M14: =IF(Raw!BH15 = "NA", "-", Raw!BH15) -> - | N14: =IF(Raw!CD15 = "NA", "-", Raw!CD15) -> - | O14: =IF(Raw!BG15 = "NA", "-", Raw!BG15) -> - | P14: =IF(Raw!AW15 = "NA", "-", SUMPRODUCT(Raw!$BT$2:$CC$2, Raw!BT15:CC15)) -> - | Q14: =IF(Raw!AW15 = "NA", "-", SUMPRODUCT(Raw!$AW$2:$BF$2, Raw!AW15:BF15)) -> - | R14: {=_xlfn.IFS(S14="YES", "Hourly", T14="YES", "Flat Rate")} -> #N/A | S14: =IF(Raw!CO15=1, "YES", "") | T14: =IF(Raw!CO15=2, "YES", "") | U14: =IF(Raw!CP15=1, "YES", "") | X14: =SUMPRODUCT(Raw!$BT$3:$CC$3, Raw!BT15:CC15) -> 0 | Y14: =SUMPRODUCT(Raw!$BT$3:$CC$3, Raw!BU15:CD15) -> 0 | Z14: =X14*5+Y14 -> 0 | AA14: =X14*261+Y14*52 -> 0 | AC14: =IF(U14="YES", F14*0.6, F14) -> 19 | AD14: =IF(U14="YES",SUMPRODUCT(Raw!$BT$3:$CC$3,Raw!BT15:CC15)*0.6,SUMPRODUCT(Raw!$BT$3:$CC$3,Raw!BT15:CC15)) -> 0 | AE14: =IF(U14="YES",SUMPRODUCT(Raw!$BT$3:$CC$3,Raw!BU15:CD15)*0.6,SUMPRODUCT(Raw!$BT$3:$CC$3,Raw!BU15:CD15)) -> 0 | AF14: =AD14*5+AE14 -> 0 | AG14: =AD14*261+AE14*52 -> 0 | AI14: =N14 -> - | AJ14: =O14 -> - | AK14: =(AI14*5+AJ14)*5.5 -> #VALUE! | AL14: =(AI14*261+AJ14*52)*5.5 -> #VALUE!
